Workbook
Name _GoBack: AUTOHOGAR!#REF!
Name entrega: '[1]Sugerencia Rendiciones '!$BP$2:$BP$11
Name tipo: '[1]Sugerencia Rendiciones '!$D$3:$D$11

Sheet AUTOHOGAR
A1: 7 | B1: =IF(A1<>0,VLOOKUP(A1,COB!A1:B9,2),"COBRADOR INEXISTENTE") -> MEDIO ELECTRONICO | D1: ENERO | E1: 2025 | F1: TOTAL | I1: EL ARRASTE ES EL DINERO PENDIENTE O A FAVOR DEL CLIENTE | AI1: 15 C 1-6 | AS1: SI EL | AU1: SI EL CLIENTE
G2: A COBRAR | I2: PAGOS | N2: SAL. REAL | O2: SALDO | P2: SALDO /P ESTAD | Q2: FECHAS | Z2: SALDO P/ | AB2: PROBLEMAS | AC2: CORDOBA | AE2: NO PASO | AH2: TOTAL | AI2: 25 C 7-X | AS2: CLIEN PAGO | AU2: DEBE ALGO | AY2: CALCULO | AZ2: MOROSO | BA2: X ADEL | BD2: CALCULO | BE2: X ADEL | BF2: MOROSO
A3: COD | B3: CLIENTE | C3: TELEFONO | D3: LOCALIDAD | E3: SOLI | F3: CTA | G3: CUOTAS | H3: ARRASTRE | I3: PAGO | J3: PAGO X ADEL | K3: PAGO ANTES | L3: X OFICINA | M3: BCO O ELECT | N3: CON MORA | O3: SISTEMA | P3: PLANILLA SALIDA | Q3: PAGO | R3: PAGARA | S3: PAGO MES ANT | T3: BAJA | U3: MOTIVO | V3: OBSERVACIONES | W3: TERMOMETRO | X3: COB | Y3: COB XX | Z3: COMISION | AA3: PAGARA | AB3: CON VEND | AC3: CON VENTAS | AD3: CON PROP. EC | AE3: EL COB | AF3: OTROS | AG3: OBSERVACIONES | AH3: CLIENTES | AI3: paramet 1 | AJ3: paramet 2 | AK3: BAJAS 7-X | AL3: CLIENTES | AM3: MOTIVOS | AN3: $ | AO3: BAJAS 1-6 | AP3: CLIENTES | AQ3: MOTIVOS | AR3: $ | AS3: PAGADOS | AT3: CLIENTES | AU3: MORO O BAJA | AV3: N° CLIEN | AW3: MOROSOS 7 -X | AX3: CLIENTES | AY3: $ | BA3: $ | BB3: MOROSOS 1 -6 | BC3: CLIENTES | BD3: $ | BF3: $
A4: 504 | B4: VEGA HERRERA ALEJANDRO | C4: 264-4479669 | D4: POCITOS | E4: 380 | F4: 80 | G4: 60000 | H4: -88500 | N4: =IF(H4>0,G4+H4-I4-J4-K4-L4-M4,G4-I4-J4-K4-L4-M4) -> 60000 | O4: =G4+H4-J4-I4-K4-L4-M4 -> -28500 | P4: =IF(G4+H4<0,0,G4+H4) -> 0 | S4: 45647 | X4: 7 | Y4: 7 | Z4: =IF(N4<0,0,N4) -> 60000 | AH4: 1 | AI4: =IF(F4<=6,15,25) -> 25 | AJ4: =IF(O4<>0,25,15) -> 25 | AK4: =IF(AI4-T4=24,1,0) -> 0 | AL4: =IF(AH4-AK4=AH4,0,AH4) -> 0 | AM4: =IF(AK4<>0,U4,0) -> 0 | AN4: =IF(AK4=1,O4,0) -> 0 | AO4: =IF(AI4-T4=14,1,0) -> 0 | AP4: =IF(AH4-AO4=AH4,0,AH4) -> 0 | AQ4: =IF(AO4<>0,U4,0) -> 0 | AR4: =IF(AO4=1,O4,0) -> 0 | AS4: =IF(SUM(I4:M4)<>0,1,0) -> 0 | AT4: =AS4 -> 0 | AU4: =IF(O4>0,1,0) -> 0 | AV4: =IF(AK4+AO4+AU4=1,AU4,0) -> 0 | AW4: =IF(AI4-AV4=24,1,0) -> 0 | AX4: =IF(AH4-AW4=AH4,0,AH4) -> 0 | AY4: =IF(AW4=1,O4,0) -> 0 | AZ4: =IF(AY4-BA4<>0,AY4,0) -> 0 | BA4: =IF(AY4<0,AY4,0) -> 0 | BB4: =IF(AI4-AV4=14,1,0) -> 0 | BC4: =IF(AH4-BB4=AH4,0,AH4) -> 0 | BD4: =IF(BB4=1,O4,0) -> 0 | BE4: =IF(BD4<0,BD4,0) -> 0 | BF4: =IF(BD4-BE4<>0,BD4,0) -> 0
A5: 557 | B5: MALLEA REYNA MARY | C5: 2647-404418 | D5: JACHAL | E5: 8677 | F5: 79 | G5: 55000 | H5: -6000 | N5: =IF(H5>0,G5+H5-I5-J5-K5-L5-M5,G5-I5-J5-K5-L5-M5) -> 55000 | O5: =G5+H5-J5-I5-K5-L5-M5 -> 49000 | P5: =IF(G5+H5<0,0,G5+H5) -> 49000 | S5: 45636 | X5: 7 | Y5: 7 | Z5: =IF(N5<0,0,N5) -> 55000 | AH5: 1 | AI5: =IF(F5<=6,15,25) -> 25 | AJ5: =IF(O5<>0,25,15) -> 25 | AK5: =IF(AI5-T5=24,1,0) -> 0 | AL5: =IF(AH5-AK5=AH5,0,AH5) -> 0 | AM5: =IF(AK5<>0,U5,0) -> 0 | AN5: =IF(AK5=1,O5,0) -> 0 | AO5: =IF(AI5-T5=14,1,0) -> 0 | AP5: =IF(AH5-AO5=AH5,0,AH5) -> 0 | AQ5: =IF(AO5<>0,U5,0) -> 0 | AR5: =IF(AO5=1,O5,0) -> 0 | AS5: =IF(SUM(I5:M5)<>0,1,0) -> 0 | AT5: =AS5 -> 0 | AU5: =IF(O5>0,1,0) -> 1 | AV5: =IF(AK5+AO5+AU5=1,AU5,0) -> 1 | AW5: =IF(AI5-AV5=24,1,0) -> 1 | AX5: =IF(AH5-AW5=AH5,0,AH5) -> 1 | AY5: =IF(AW5=1,O5,0) -> 49000 | AZ5: =IF(AY5-BA5<>0,AY5,0) -> 49000 | BA5: =IF(AY5<0,AY5,0) -> 0 | BB5: =IF(AI5-AV5=14,1,0) -> 0 | BC5: =IF(AH5-BB5=AH5,0,AH5) -> 0 | BD5: =IF(BB5=1,O5,0) -> 0 | BE5: =IF(BD5<0,BD5,0) -> 0 | BF5: =IF(BD5-BE5<>0,BD5,0) -> 0
A6: 756 | B6: AGUERO EZEQUIEL JACINTO | C6: 264-5091143 | D6: CAUCETE | E6: 357 | F6: 75 | G6: 30000 | H6: 0 | N6: =IF(H6>0,G6+H6-I6-J6-K6-L6-M6,G6-I6-J6-K6-L6-M6) -> 30000 | O6: =G6+H6-J6-I6-K6-L6-M6 -> 30000 | P6: =IF(G6+H6<0,0,G6+H6) -> 30000 | Q6: 45663 | S6: 45631 | V6: MERCADO PAGO | X6: 7 | Y6: 7 | Z6: =IF(N6<0,0,N6) -> 30000 | AH6: 1 | AI6: =IF(F6<=6,15,25) -> 25 | AJ6: =IF(O6<>0,25,15) -> 25 | AK6: =IF(AI6-T6=24,1,0) -> 0 | AL6: =IF(AH6-AK6=AH6,0,AH6) -> 0 | AM6: =IF(AK6<>0,U6,0) -> 0 | AN6: =IF(AK6=1,O6,0) -> 0 | AO6: =IF(AI6-T6=14,1,0) -> 0 | AP6: =IF(AH6-AO6=AH6,0,AH6) -> 0 | AQ6: =IF(AO6<>0,U6,0) -> 0 | AR6: =IF(AO6=1,O6,0) -> 0 | AS6: =IF(SUM(I6:M6)<>0,1,0) -> 0 | AT6: =AS6 -> 0 | AU6: =IF(O6>0,1,0) -> 1 | AV6: =IF(AK6+AO6+AU6=1,AU6,0) -> 1 | AW6: =IF(AI6-AV6=24,1,0) -> 1 | AX6: =IF(AH6-AW6=AH6,0,AH6) -> 1 | AY6: =IF(AW6=1,O6,0) -> 30000 | AZ6: =IF(AY6-BA6<>0,AY6,0) -> 30000 | BA6: =IF(AY6<0,AY6,0) -> 0 | BB6: =IF(AI6-AV6=14,1,0) -> 0 | BC6: =IF(AH6-BB6=AH6,0,AH6) -> 0 | BD6: =IF(BB6=1,O6,0) -> 0 | BE6: =IF(BD6<0,BD6,0) -> 0 | BF6: =IF(BD6-BE6<>0,BD6,0) -> 0
A7: 816 | B7: GUEVARA ANTONIO NICOLAS | C7: 264-4837119 | D7: HUACO | E7: 9287 | F7: 74 | G7: 40000 | H7: 0 | N7: =IF(H7>0,G7+H7-I7-J7-K7-L7-M7,G7-I7-J7-K7-L7-M7) -> 40000 | O7: =G7+H7-J7-I7-K7-L7-M7 -> 40000 | P7: =IF(G7+H7<0,0,G7+H7) -> 40000 | Q7: 45659 | S7: 45630 | V7: MERCADO PAGO | X7: 7 | Y7: 7 | Z7: =IF(N7<0,0,N7) -> 40000 | AH7: 1 | AI7: =IF(F7<=6,15,25) -> 25 | AJ7: =IF(O7<>0,25,15) -> 25 | AK7: =IF(AI7-T7=24,1,0) -> 0 | AL7: =IF(AH7-AK7=AH7,0,AH7) -> 0 | AM7: =IF(AK7<>0,U7,0) -> 0 | AN7: =IF(AK7=1,O7,0) -> 0 | AO7: =IF(AI7-T7=14,1,0) -> 0 | AP7: =IF(AH7-AO7=AH7,0,AH7) -> 0 | AQ7: =IF(AO7<>0,U7,0) -> 0 | AR7: =IF(AO7=1,O7,0) -> 0 | AS7: =IF(SUM(I7:M7)<>0,1,0) -> 0 | AT7: =AS7 -> 0 | AU7: =IF(O7>0,1,0) -> 1 | AV7: =IF(AK7+AO7+AU7=1,AU7,0) -> 1 | AW7: =IF(AI7-AV7=24,1,0) -> 1 | AX7: =IF(AH7-AW7=AH7,0,AH7) -> 1 | AY7: =IF(AW7=1,O7,0) -> 40000 | AZ7: =IF(AY7-BA7<>0,AY7,0) -> 40000 | BA7: =IF(AY7<0,AY7,0) -> 0 | BB7: =IF(AI7-AV7=14,1,0) -> 0 | BC7: =IF(AH7-BB7=AH7,0,AH7) -> 0 | BD7: =IF(BB7=1,O7,0) -> 0 | BE7: =IF(BD7<0,BD7,0) -> 0 | BF7: =IF(BD7-BE7<>0,BD7,0) -> 0
A8: 823 | B8: JOFRE ELIZABETH DEL VALLE | C8: 264-4122541 | D8: JACHAL | E8: 9375 | F8: 74 | G8: 30000 | H8: -3500 | N8: =IF(H8>0,G8+H8-I8-J8-K8-L8-M8,G8-I8-J8-K8-L8-M8) -> 30000 | O8: =G8+H8-J8-I8-K8-L8-M8 -> 26500 | P8: =IF(G8+H8<0,0,G8+H8) -> 26500 | S8: 45635 | X8: 7 | Y8: 7 | Z8: =IF(N8<0,0,N8) -> 30000 | AH8: 1 | AI8: =IF(F8<=6,15,25) -> 25 | AJ8: =IF(O8<>0,25,15) -> 25 | AK8: =IF(AI8-T8=24,1,0) -> 0 | AL8: =IF(AH8-AK8=AH8,0,AH8) -> 0 | AM8: =IF(AK8<>0,U8,0) -> 0 | AN8: =IF(AK8=1,O8,0) -> 0 | AO8: =IF(AI8-T8=14,1,0) -> 0 | AP8: =IF(AH8-AO8=AH8,0,AH8) -> 0 | AQ8: =IF(AO8<>0,U8,0) -> 0 | AR8: =IF(AO8=1,O8,0) -> 0 | AS8: =IF(SUM(I8:M8)<>0,1,0) -> 0 | AT8: =AS8 -> 0 | AU8: =IF(O8>0,1,0) -> 1 | AV8: =IF(AK8+AO8+AU8=1,AU8,0) -> 1 | AW8: =IF(AI8-AV8=24,1,0) -> 1 | AX8: =IF(AH8-AW8=AH8,0,AH8) -> 1 | AY8: =IF(AW8=1,O8,0) -> 26500 | AZ8: =IF(AY8-BA8<>0,AY8,0) -> 26500 | BA8: =IF(AY8<0,AY8,0) -> 0 | BB8: =IF(AI8-AV8=14,1,0) -> 0 | BC8: =IF(AH8-BB8=AH8,0,AH8) -> 0 | BD8: =IF(BB8=1,O8,0) -> 0 | BE8: =IF(BD8<0,BD8,0) -> 0 | BF8: =IF(BD8-BE8<>0,BD8,0) -> 0
A9: 834 | B9: BALMACEDA ESTER MARIA | C9: 264-7420363 | D9: JACHAL | E9: 9034 | F9: 74 | G9: 60000 | H9: -4000 | N9: =IF(H9>0,G9+H9-I9-J9-K9-L9-M9,G9-I9-J9-K9-L9-M9) -> 60000 | O9: =G9+H9-J9-I9-K9-L9-M9 -> 56000 | P9: =IF(G9+H9<0,0,G9+H9) -> 56000 | S9: 45636 | X9: 7 | Y9: 7 | Z9: =IF(N9<0,0,N9) -> 60000 | AH9: 1 | AI9: =IF(F9<=6,15,25) -> 25 | AJ9: =IF(O9<>0,25,15) -> 25 | AK9: =IF(AI9-T9=24,1,0) -> 0 | AL9: =IF(AH9-AK9=AH9,0,AH9) -> 0 | AM9: =IF(AK9<>0,U9,0) -> 0 | AN9: =IF(AK9=1,O9,0) -> 0 | AO9: =IF(AI9-T9=14,1,0) -> 0 | AP9: =IF(AH9-AO9=AH9,0,AH9) -> 0 | AQ9: =IF(AO9<>0,U9,0) -> 0 | AR9: =IF(AO9=1,O9,0) -> 0 | AS9: =IF(SUM(I9:M9)<>0,1,0) -> 0 | AT9: =AS9 -> 0 | AU9: =IF(O9>0,1,0) -> 1 | AV9: =IF(AK9+AO9+AU9=1,AU9,0) -> 1 | AW9: =IF(AI9-AV9=24,1,0) -> 1 | AX9: =IF(AH9-AW9=AH9,0,AH9) -> 1 | AY9: =IF(AW9=1,O9,0) -> 56000 | AZ9: =IF(AY9-BA9<>0,AY9,0) -> 56000 | BA9: =IF(AY9<0,AY9,0) -> 0 | BB9: =IF(AI9-AV9=14,1,0) -> 0 | BC9: =IF(AH9-BB9=AH9,0,AH9) -> 0 | BD9: =IF(BB9=1,O9,0) -> 0 | BE9: =IF(BD9<0,BD9,0) -> 0 | BF9: =IF(BD9-BE9<>0,BD9,0) -> 0
A10: 1021 | B10: ARIAS LOPEZ JAVIER ALEJANDRO | C10: 264-5622309 | D10: CHIMBAS | E10: 300 | F10: 69 | G10: 55000 | H10: 0 | N10: =IF(H10>0,G10+H10-I10-J10-K10-L10-M10,G10-I10-J10-K10-L10-M10) -> 55000 | O10: =G10+H10-J10-I10-K10-L10-M10 -> 55000 | P10: =IF(G10+H10<0,0,G10+H10) -> 55000 | S10: 45640 | X10: 7 | Y10: 7 | Z10: =IF(N10<0,0,N10) -> 55000 | AH10: 1 | AI10: =IF(F10<=6,15,25) -> 25 | AJ10: =IF(O10<>0,25,15) -> 25 | AK10: =IF(AI10-T10=24,1,0) -> 0 | AL10: =IF(AH10-AK10=AH10,0,AH10) -> 0 | AM10: =IF(AK10<>0,U10,0) -> 0 | AN10: =IF(AK10=1,O10,0) -> 0 | AO10: =IF(AI10-T10=14,1,0) -> 0 | AP10: =IF(AH10-AO10=AH10,0,AH10) -> 0 | AQ10: =IF(AO10<>0,U10,0) -> 0 | AR10: =IF(AO10=1,O10,0) -> 0 | AS10: =IF(SUM(I10:M10)<>0,1,0) -> 0 | AT10: =AS10 -> 0 | AU10: =IF(O10>0,1,0) -> 1 | AV10: =IF(AK10+AO10+AU10=1,AU10,0) -> 1 | AW10: =IF(AI10-AV10=24,1,0) -> 1 | AX10: =IF(AH10-AW10=AH10,0,AH10) -> 1 | AY10: =IF(AW10=1,O10,0) -> 55000 | AZ10: =IF(AY10-BA10<>0,AY10,0) -> 55000 | BA10: =IF(AY10<0,AY10,0) -> 0 | BB10: =IF(AI10-AV10=14,1,0) -> 0 | BC10: =IF(AH10-BB10=AH10,0,AH10) -> 0 | BD10: =IF(BB10=1,O10,0) -> 0 | BE10: =IF(BD10<0,BD10,0) -> 0 | BF10: =IF(BD10-BE10<>0,BD10,0) -> 0
A11: 1108 | B11: MANRIQUE MARIA DEL CARMEN | C11: 264-4754914 | D11: 9 DE JULIO | E11: 9341 | F11: 67 | G11: 60000 | H11: -12000 | N11: =IF(H11>0,G11+H11-I11-J11-K11-L11-M11,G11-I11-J11-K11-L11-M11) -> 60000 | O11: =G11+H11-J11-I11-K11-L11-M11 -> 48000 | P11: =IF(G11+H11<0,0,G11+H11) -> 48000 | S11: 45636 | X11: 7 | Y11: 7 | Z11: =IF(N11<0,0,N11) -> 60000 | AH11: 1 | AI11: =IF(F11<=6,15,25) -> 25 | AJ11: =IF(O11<>0,25,15) -> 25 | AK11: =IF(AI11-T11=24,1,0) -> 0 | AL11: =IF(AH11-AK11=AH11,0,AH11) -> 0 | AM11: =IF(AK11<>0,U11,0) -> 0 | AN11: =IF(AK11=1,O11,0) -> 0 | AO11: =IF(AI11-T11=14,1,0) -> 0 | AP11: =IF(AH11-AO11=AH11,0,AH11) -> 0 | AQ11: =IF(AO11<>0,U11,0) -> 0 | AR11: =IF(AO11=1,O11,0) -> 0 | AS11: =IF(SUM(I11:M11)<>0,1,0) -> 0 | AT11: =AS11 -> 0 | AU11: =IF(O11>0,1,0) -> 1 | AV11: =IF(AK11+AO11+AU11=1,AU11,0) -> 1 | AW11: =IF(AI11-AV11=24,1,0) -> 1 | AX11: =IF(AH11-AW11=AH11,0,AH11) -> 1 | AY11: =IF(AW11=1,O11,0) -> 48000 | AZ11: =IF(AY11-BA11<>0,AY11,0) -> 48000 | BA11: =IF(AY11<0,AY11,0) -> 0 | BB11: =IF(AI11-AV11=14,1,0) -> 0 | BC11: =IF(AH11-BB11=AH11,0,AH11) -> 0 | BD11: =IF(BB11=1,O11,0) -> 0 | BE11: =IF(BD11<0,BD11,0) -> 0 | BF11: =IF(BD11-BE11<>0,BD11,0) -> 0
A12: 1186 | B12: GARAY MARCELO | C12: 264-5269535 | D12: SAN JUAN | E12: 8984 | F12: 65 | G12: 60000 | H12: -24000 | N12: =IF(H12>0,G12+H12-I12-J12-K12-L12-M12,G12-I12-J12-K12-L12-M12) -> 60000 | O12: =G12+H12-J12-I12-K12-L12-M12 -> 36000 | P12: =IF(G12+H12<0,0,G12+H12) -> 36000 | Q12: 45659 | S12: 45628 | V12: MERCADO PAGO | X12: 7 | Y12: 7 | Z12: =IF(N12<0,0,N12) -> 60000 | AH12: 1 | AI12: =IF(F12<=6,15,25) -> 25 | AJ12: =IF(O12<>0,25,15) -> 25 | AK12: =IF(AI12-T12=24,1,0) -> 0 | AL12: =IF(AH12-AK12=AH12,0,AH12) -> 0 | AM12: =IF(AK12<>0,U12,0) -> 0 | AN12: =IF(AK12=1,O12,0) -> 0 | AO12: =IF(AI12-T12=14,1,0) -> 0 | AP12: =IF(AH12-AO12=AH12,0,AH12) -> 0 | AQ12: =IF(AO12<>0,U12,0) -> 0 | AR12: =IF(AO12=1,O12,0) -> 0 | AS12: =IF(SUM(I12:M12)<>0,1,0) -> 0 | AT12: =AS12 -> 0 | AU12: =IF(O12>0,1,0) -> 1 | AV12: =IF(AK12+AO12+AU12=1,AU12,0) -> 1 | AW12: =IF(AI12-AV12=24,1,0) -> 1 | AX12: =IF(AH12-AW12=AH12,0,AH12) -> 1 | AY12: =IF(AW12=1,O12,0) -> 36000 | AZ12: =IF(AY12-BA12<>0,AY12,0) -> 36000 | BA12: =IF(AY12<0,AY12,0) -> 0 | BB12: =IF(AI12-AV12=14,1,0) -> 0 | BC12: =IF(AH12-BB12=AH12,0,AH12) -> 0 | BD12: =IF(BB12=1,O12,0) -> 0 | BE12: =IF(BD12<0,BD12,0) -> 0 | BF12: =IF(BD12-BE12<>0,BD12,0) -> 0
A13: 1413 | B13: OLMOS CLAUDIO EZEQUIEL | C13: 264-5701783 | D13: CAUCETE | E13: 8855 | F13: 59 | G13: 55000 | H13: -60000 | N13: =IF(H13>0,G13+H13-I13-J13-K13-L13-M13,G13-I13-J13-K13-L13-M13) -> 55000 | O13: =G13+H13-J13-I13-K13-L13-M13 -> -5000 | P13: =IF(G13+H13<0,0,G13+H13) -> 0 | S13: 45636 | X13: 7 | Y13: 7 | Z13: =IF(N13<0,0,N13) -> 55000 | AH13: 1 | AI13: =IF(F13<=6,15,25) -> 25 | AJ13: =IF(O13<>0,25,15) -> 25 | AK13: =IF(AI13-T13=24,1,0) -> 0 | AL13: =IF(AH13-AK13=AH13,0,AH13) -> 0 | AM13: =IF(AK13<>0,U13,0) -> 0 | AN13: =IF(AK13=1,O13,0) -> 0 | AO13: =IF(AI13-T13=14,1,0) -> 0 | AP13: =IF(AH13-AO13=AH13,0,AH13) -> 0 | AQ13: =IF(AO13<>0,U13,0) -> 0 | AR13: =IF(AO13=1,O13,0) -> 0 | AS13: =IF(SUM(I13:M13)<>0,1,0) -> 0 | AT13: =AS13 -> 0 | AU13: =IF(O13>0,1,0) -> 0 | AV13: =IF(AK13+AO13+AU13=1,AU13,0) -> 0 | AW13: =IF(AI13-AV13=24,1,0) -> 0 | AX13: =IF(AH13-AW13=AH13,0,AH13) -> 0 | AY13: =IF(AW13=1,O13,0) -> 0 | AZ13: =IF(AY13-BA13<>0,AY13,0) -> 0 | BA13: =IF(AY13<0,AY13,0) -> 0 | BB13: =IF(AI13-AV13=14,1,0) -> 0 | BC13: =IF(AH13-BB13=AH13,0,AH13) -> 0 | BD13: =IF(BB13=1,O13,0) -> 0 | BE13: =IF(BD13<0,BD13,0) -> 0 | BF13: =IF(BD13-BE13<>0,BD13,0) -> 0
A14: 1417 | B14: GARAY MARCELO ROBERTO | C14: 264-5269535 | D14: SAN JUAN | E14: 8539 | F14: 58 | G14: 60000 | H14: -6000 | N14: =IF(H14>0,G14+H14-I14-J14-K14-L14-M14,G14-I14-J14-K14-L14-M14) -> 60000 | O14: =G14+H14-J14-I14-K14-L14-M14 -> 54000 | P14: =IF(G14+H14<0,0,G14+H14) -> 54000 | Q14: 45659 | S14: 45628 | V14: MERCADO PAGO | X14: 7 | Y14: 7 | Z14: =IF(N14<0,0,N14) -> 60000 | AH14: 1 | AI14: =IF(F14<=6,15,25) -> 25 | AJ14: =IF(O14<>0,25,15) -> 25 | AK14: =IF(AI14-T14=24,1,0) -> 0 | AL14: =IF(AH14-AK14=AH14,0,AH14) -> 0 | AM14: =IF(AK14<>0,U14,0) -> 0 | AN14: =IF(AK14=1,O14,0) -> 0 | AO14: =IF(AI14-T14=14,1,0) -> 0 | AP14: =IF(AH14-AO14=AH14,0,AH14) -> 0 | AQ14: =IF(AO14<>0,U14,0) -> 0 | AR14: =IF(AO14=1,O14,0) -> 0 | AS14: =IF(SUM(I14:M14)<>0,1,0) -> 0 | AT14: =AS14 -> 0 | AU14: =IF(O14>0,1,0) -> 1 | AV14: =IF(AK14+AO14+AU14=1,AU14,0) -> 1 | AW14: =IF(AI14-AV14=24,1,0) -> 1 | AX14: =IF(AH14-AW14=AH14,0,AH14) -> 1 | AY14: =IF(AW14=1,O14,0) -> 54000 | AZ14: =IF(AY14-BA14<>0,AY14,0) -> 54000 | BA14: =IF(AY14<0,AY14,0) -> 0 | BB14: =IF(AI14-AV14=14,1,0) -> 0 | BC14: =IF(AH14-BB14=AH14,0,AH14) -> 0 | BD14: =IF(BB14=1,O14,0) -> 0 | BE14: =IF(BD14<0,BD14,0) -> 0 | BF14: =IF(BD14-BE14<>0,BD14,0) -> 0
A15: 1449 | B15: ESCUELA ANA LORENA | C15: 264-5424491 | D15: POCITOS | E15: 8865 | F15: 57 | G15: 60000 | H15: 0 | N15: =IF(H15>0,G15+H15-I15-J15-K15-L15-M15,G15-I15-J15-K15-L15-M15) -> 60000 | O15: =G15+H15-J15-I15-K15-L15-M15 -> 60000 | P15: =IF(G15+H15<0,0,G15+H15) -> 60000 | S15: 45656 | X15: 7 | Y15: 7 | Z15: =IF(N15<0,0,N15) -> 60000 | AH15: 1 | AI15: =IF(F15<=6,15,25) -> 25 | AJ15: =IF(O15<>0,25,15) -> 25 | AK15: =IF(AI15-T15=24,1,0) -> 0 | AL15: =IF(AH15-AK15=AH15,0,AH15) -> 0 | AM15: =IF(AK15<>0,U15,0) -> 0 | AN15: =IF(AK15=1,O15,0) -> 0 | AO15: =IF(AI15-T15=14,1,0) -> 0 | AP15: =IF(AH15-AO15=AH15,0,AH15) -> 0 | AQ15: =IF(AO15<>0,U15,0) -> 0 | AR15: =IF(AO15=1,O15,0) -> 0 | AS15: =IF(SUM(I15:M15)<>0,1,0) -> 0 | AT15: =AS15 -> 0 | AU15: =IF(O15>0,1,0) -> 1 | AV15: =IF(AK15+AO15+AU15=1,AU15,0) -> 1 | AW15: =IF(AI15-AV15=24,1,0) -> 1 | AX15: =IF(AH15-AW15=AH15,0,AH15) -> 1 | AY15: =IF(AW15=1,O15,0) -> 60000 | AZ15: =IF(AY15-BA15<>0,AY15,0) -> 60000 | BA15: =IF(AY15<0,AY15,0) -> 0 | BB15: =IF(AI15-AV15=14,1,0) -> 0 | BC15: =IF(AH15-BB15=AH15,0,AH15) -> 0 | BD15: =IF(BB15=1,O15,0) -> 0 | BE15: =IF(BD15<0,BD15,0) -> 0 | BF15: =IF(BD15-BE15<>0,BD15,0) -> 0
A16: 1457 | B16: PASTEN EMILCE SABRINA | C16: 264-4739119 | D16: RIVADAVIA | E16: 8864 | F16: 57 | G16: 60000 | H16: -15000 | N16: =IF(H16>0,G16+H16-I16-J16-K16-L16-M16,G16-I16-J16-K16-L16-M16) -> 60000 | O16: =G16+H16-J16-I16-K16-L16-M16 -> 45000 | P16: =IF(G16+H16<0,0,G16+H16) -> 45000 | S16: 45643 | X16: 7 | Y16: 7 | Z16: =IF(N16<0,0,N16) -> 60000 | AH16: 1 | AI16: =IF(F16<=6,15,25) -> 25 | AJ16: =IF(O16<>0,25,15) -> 25 | AK16: =IF(AI16-T16=24,1,0) -> 0 | AL16: =IF(AH16-AK16=AH16,0,AH16) -> 0 | AM16: =IF(AK16<>0,U16,0) -> 0 | AN16: =IF(AK16=1,O16,0) -> 0 | AO16: =IF(AI16-T16=14,1,0) -> 0 | AP16: =IF(AH16-AO16=AH16,0,AH16) -> 0 | AQ16: =IF(AO16<>0,U16,0) -> 0 | AR16: =IF(AO16=1,O16,0) -> 0 | AS16: =IF(SUM(I16:M16)<>0,1,0) -> 0 | AT16: =AS16 -> 0 | AU16: =IF(O16>0,1,0) -> 1 | AV16: =IF(AK16+AO16+AU16=1,AU16,0) -> 1 | AW16: =IF(AI16-AV16=24,1,0) -> 1 | AX16: =IF(AH16-AW16=AH16,0,AH16) -> 1 | AY16: =IF(AW16=1,O16,0) -> 45000 | AZ16: =IF(AY16-BA16<>0,AY16,0) -> 45000 | BA16: =IF(AY16<0,AY16,0) -> 0 | BB16: =IF(AI16-AV16=14,1,0) -> 0 | BC16: =IF(AH16-BB16=AH16,0,AH16) -> 0 | BD16: =IF(BB16=1,O16,0) -> 0 | BE16: =IF(BD16<0,BD16,0) -> 0 | BF16: =IF(BD16-BE16<>0,BD16,0) -> 0
A17: 1462 | B17: GARAY JUAN ARIEL | C17: 264-4894243 | D17: CHIMBAS | E17: 8885 | F17: 57 | G17: 60000 | H17: 0 | N17: =IF(H17>0,G17+H17-I17-J17-K17-L17-M17,G17-I17-J17-K17-L17-M17) -> 60000 | O17: =G17+H17-J17-I17-K17-L17-M17 -> 60000 | P17: =IF(G17+H17<0,0,G17+H17) -> 60000 | S17: 45643 | X17: 7 | Y17: 7 | Z17: =IF(N17<0,0,N17) -> 60000 | AH17: 1 | AI17: =IF(F17<=6,15,25) -> 25 | AJ17: =IF(O17<>0,25,15) -> 25 | AK17: =IF(AI17-T17=24,1,0) -> 0 | AL17: =IF(AH17-AK17=AH17,0,AH17) -> 0 | AM17: =IF(AK17<>0,U17,0) -> 0 | AN17: =IF(AK17=1,O17,0) -> 0 | AO17: =IF(AI17-T17=14,1,0) -> 0 | AP17: =IF(AH17-AO17=AH17,0,AH17) -> 0 | AQ17: =IF(AO17<>0,U17,0) -> 0 | AR17: =IF(AO17=1,O17,0) -> 0 | AS17: =IF(SUM(I17:M17)<>0,1,0) -> 0 | AT17: =AS17 -> 0 | AU17: =IF(O17>0,1,0) -> 1 | AV17: =IF(AK17+AO17+AU17=1,AU17,0) -> 1 | AW17: =IF(AI17-AV17=24,1,0) -> 1 | AX17: =IF(AH17-AW17=AH17,0,AH17) -> 1 | AY17: =IF(AW17=1,O17,0) -> 60000 | AZ17: =IF(AY17-BA17<>0,AY17,0) -> 60000 | BA17: =IF(AY17<0,AY17,0) -> 0 | BB17: =IF(AI17-AV17=14,1,0) -> 0 | BC17: =IF(AH17-BB17=AH17,0,AH17) -> 0 | BD17: =IF(BB17=1,O17,0) -> 0 | BE17: =IF(BD17<0,BD17,0) -> 0 | BF17: =IF(BD17-BE17<>0,BD17,0) -> 0
A18: 1463 | B18: GARAY JUAN ARIEL | C18: 264-4894243 | D18: CHIMBAS | E18: 8884 | F18: 57 | G18: 60000 | H18: 0 | N18: =IF(H18>0,G18+H18-I18-J18-K18-L18-M18,G18-I18-J18-K18-L18-M18) -> 60000 | O18: =G18+H18-J18-I18-K18-L18-M18 -> 60000 | P18: =IF(G18+H18<0,0,G18+H18) -> 60000 | S18: 45643 | X18: 7 | Y18: 7 | Z18: =IF(N18<0,0,N18) -> 60000 | AH18: 1 | AI18: =IF(F18<=6,15,25) -> 25 | AJ18: =IF(O18<>0,25,15) -> 25 | AK18: =IF(AI18-T18=24,1,0) -> 0 | AL18: =IF(AH18-AK18=AH18,0,AH18) -> 0 | AM18: =IF(AK18<>0,U18,0) -> 0 | AN18: =IF(AK18=1,O18,0) -> 0 | AO18: =IF(AI18-T18=14,1,0) -> 0 | AP18: =IF(AH18-AO18=AH18,0,AH18) -> 0 | AQ18: =IF(AO18<>0,U18,0) -> 0 | AR18: =IF(AO18=1,O18,0) -> 0 | AS18: =IF(SUM(I18:M18)<>0,1,0) -> 0 | AT18: =AS18 -> 0 | AU18: =IF(O18>0,1,0) -> 1 | AV18: =IF(AK18+AO18+AU18=1,AU18,0) -> 1 | AW18: =IF(AI18-AV18=24,1,0) -> 1 | AX18: =IF(AH18-AW18=AH18,0,AH18) -> 1 | AY18: =IF(AW18=1,O18,0) -> 60000 | AZ18: =IF(AY18-BA18<>0,AY18,0) -> 60000 | BA18: =IF(AY18<0,AY18,0) -> 0 | BB18: =IF(AI18-AV18=14,1,0) -> 0 | BC18: =IF(AH18-BB18=AH18,0,AH18) -> 0 | BD18: =IF(BB18=1,O18,0) -> 0 | BE18: =IF(BD18<0,BD18,0) -> 0 | BF18: =IF(BD18-BE18<>0,BD18,0) -> 0
A19: 1509 | B19: MAÑE MERCEDES CAROLINA | C19: 264-6118911 | D19: RAWSON | E19: 8866 | F19: 56 | G19: 60000 | H19: 0 | N19: =IF(H19>0,G19+H19-I19-J19-K19-L19-M19,G19-I19-J19-K19-L19-M19) -> 60000 | O19: =G19+H19-J19-I19-K19-L19-M19 -> 60000 | P19: =IF(G19+H19<0,0,G19+H19) -> 60000 | S19: 45638 | X19: 7 | Y19: 7 | Z19: =IF(N19<0,0,N19) -> 60000 | AH19: 1 | AI19: =IF(F19<=6,15,25) -> 25 | AJ19: =IF(O19<>0,25,15) -> 25 | AK19: =IF(AI19-T19=24,1,0) -> 0 | AL19: =IF(AH19-AK19=AH19,0,AH19) -> 0 | AM19: =IF(AK19<>0,U19,0) -> 0 | AN19: =IF(AK19=1,O19,0) -> 0 | AO19: =IF(AI19-T19=14,1,0) -> 0 | AP19: =IF(AH19-AO19=AH19,0,AH19) -> 0 | AQ19: =IF(AO19<>0,U19,0) -> 0 | AR19: =IF(AO19=1,O19,0) -> 0 | AS19: =IF(SUM(I19:M19)<>0,1,0) -> 0 | AT19: =AS19 -> 0 | AU19: =IF(O19>0,1,0) -> 1 | AV19: =IF(AK19+AO19+AU19=1,AU19,0) -> 1 | AW19: =IF(AI19-AV19=24,1,0) -> 1 | AX19: =IF(AH19-AW19=AH19,0,AH19) -> 1 | AY19: =IF(AW19=1,O19,0) -> 60000 | AZ19: =IF(AY19-BA19<>0,AY19,0) -> 60000 | BA19: =IF(AY19<0,AY19,0) -> 0 | BB19: =IF(AI19-AV19=14,1,0) -> 0 | BC19: =IF(AH19-BB19=AH19,0,AH19) -> 0 | BD19: =IF(BB19=1,O19,0) -> 0 | BE19: =IF(BD19<0,BD19,0) -> 0 | BF19: =IF(BD19-BE19<>0,BD19,0) -> 0
A20: 1526 | B20: LUNA OLGA | C20: 264-4189233 | D20: JACHAL | E20: 9557 | F20: 55 | G20: 30000 | H20: -70700 | N20: =IF(H20>0,G20+H20-I20-J20-K20-L20-M20,G20-I20-J20-K20-L20-M20) -> 30000 | O20: =G20+H20-J20-I20-K20-L20-M20 -> -40700 | P20: =IF(G20+H20<0,0,G20+H20) -> 0 | S20: 45640 | X20: 7 | Y20: 7 | Z20: =IF(N20<0,0,N20) -> 30000 | AH20: 1 | AI20: =IF(F20<=6,15,25) -> 25 | AJ20: =IF(O20<>0,25,15) -> 25 | AK20: =IF(AI20-T20=24,1,0) -> 0 | AL20: =IF(AH20-AK20=AH20,0,AH20) -> 0 | AM20: =IF(AK20<>0,U20,0) -> 0 | AN20: =IF(AK20=1,O20,0) -> 0 | AO20: =IF(AI20-T20=14,1,0) -> 0 | AP20: =IF(AH20-AO20=AH20,0,AH20) -> 0 | AQ20: =IF(AO20<>0,U20,0) -> 0 | AR20: =IF(AO20=1,O20,0) -> 0 | AS20: =IF(SUM(I20:M20)<>0,1,0) -> 0 | AT20: =AS20 -> 0 | AU20: =IF(O20>0,1,0) -> 0 | AV20: =IF(AK20+AO20+AU20=1,AU20,0) -> 0 | AW20: =IF(AI20-AV20=24,1,0) -> 0 | AX20: =IF(AH20-AW20=AH20,0,AH20) -> 0 | AY20: =IF(AW20=1,O20,0) -> 0 | AZ20: =IF(AY20-BA20<>0,AY20,0) -> 0 | BA20: =IF(AY20<0,AY20,0) -> 0 | BB20: =IF(AI20-AV20=14,1,0) -> 0 | BC20: =IF(AH20-BB20=AH20,0,AH20) -> 0 | BD20: =IF(BB20=1,O20,0) -> 0 | BE20: =IF(BD20<0,BD20,0) -> 0 | BF20: =IF(BD20-BE20<>0,BD20,0) -> 0
A21: 1589 | B21: TRIGO ALEJANDRO JOSE | C21: 264-4118920 | D21: RAWSON | E21: 9614 | F21: 55 | G21: 30000 | H21: -29000 | N21: =IF(H21>0,G21+H21-I21-J21-K21-L21-M21,G21-I21-J21-K21-L21-M21) -> 30000 | O21: =G21+H21-J21-I21-K21-L21-M21 -> 1000 | P21: =IF(G21+H21<0,0,G21+H21) -> 1000 | S21: 45645 | X21: 7 | Y21: 7 | Z21: =IF(N21<0,0,N21) -> 30000 | AH21: 1 | AI21: =IF(F21<=6,15,25) -> 25 | AJ21: =IF(O21<>0,25,15) -> 25 | AK21: =IF(AI21-T21=24,1,0) -> 0 | AL21: =IF(AH21-AK21=AH21,0,AH21) -> 0 | AM21: =IF(AK21<>0,U21,0) -> 0 | AN21: =IF(AK21=1,O21,0) -> 0 | AO21: =IF(AI21-T21=14,1,0) -> 0 | AP21: =IF(AH21-AO21=AH21,0,AH21) -> 0 | AQ21: =IF(AO21<>0,U21,0) -> 0 | AR21: =IF(AO21=1,O21,0) -> 0 | AS21: =IF(SUM(I21:M21)<>0,1,0) -> 0 | AT21: =AS21 -> 0 | AU21: =IF(O21>0,1,0) -> 1 | AV21: =IF(AK21+AO21+AU21=1,AU21,0) -> 1 | AW21: =IF(AI21-AV21=24,1,0) -> 1 | AX21: =IF(AH21-AW21=AH21,0,AH21) -> 1 | AY21: =IF(AW21=1,O21,0) -> 1000 | AZ21: =IF(AY21-BA21<>0,AY21,0) -> 1000 | BA21: =IF(AY21<0,AY21,0) -> 0 | BB21: =IF(AI21-AV21=14,1,0) -> 0 | BC21: =IF(AH21-BB21=AH21,0,AH21) -> 0 | BD21: =IF(BB21=1,O21,0) -> 0 | BE21: =IF(BD21<0,BD21,0) -> 0 | BF21: =IF(BD21-BE21<>0,BD21,0) -> 0
A22: 1597 | B22: ALMAZAN JUAN ARIEL | C22: 264-6245764 | D22: RAWSON | E22: 9625 | F22: 54 | G22: 60000 | H22: -3500 | N22: =IF(H22>0,G22+H22-I22-J22-K22-L22-M22,G22-I22-J22-K22-L22-M22) -> 60000 | O22: =G22+H22-J22-I22-K22-L22-M22 -> 56500 | P22: =IF(G22+H22<0,0,G22+H22) -> 56500 | S22: 45656 | X22: 7 | Y22: 7 | Z22: =IF(N22<0,0,N22) -> 60000 | AH22: 1 | AI22: =IF(F22<=6,15,25) -> 25 | AJ22: =IF(O22<>0,25,15) -> 25 | AK22: =IF(AI22-T22=24,1,0) -> 0 | AL22: =IF(AH22-AK22=AH22,0,AH22) -> 0 | AM22: =IF(AK22<>0,U22,0) -> 0 | AN22: =IF(AK22=1,O22,0) -> 0 | AO22: =IF(AI22-T22=14,1,0) -> 0 | AP22: =IF(AH22-AO22=AH22,0,AH22) -> 0 | AQ22: =IF(AO22<>0,U22,0) -> 0 | AR22: =IF(AO22=1,O22,0) -> 0 | AS22: =IF(SUM(I22:M22)<>0,1,0) -> 0 | AT22: =AS22 -> 0 | AU22: =IF(O22>0,1,0) -> 1 | AV22: =IF(AK22+AO22+AU22=1,AU22,0) -> 1 | AW22: =IF(AI22-AV22=24,1,0) -> 1 | AX22: =IF(AH22-AW22=AH22,0,AH22) -> 1 | AY22: =IF(AW22=1,O22,0) -> 56500 | AZ22: =IF(AY22-BA22<>0,AY22,0) -> 56500 | BA22: =IF(AY22<0,AY22,0) -> 0 | BB22: =IF(AI22-AV22=14,1,0) -> 0 | BC22: =IF(AH22-BB22=AH22,0,AH22) -> 0 | BD22: =IF(BB22=1,O22,0) -> 0 | BE22: =IF(BD22<0,BD22,0) -> 0 | BF22: =IF(BD22-BE22<>0,BD22,0) -> 0
A23: 1601 | B23: BUSTOS ELIZABETH NOEMI | C23: 264-5207638 | D23: SANTA LUCIA | E23: 9594 | F23: 54 | G23: 60000 | H23: 0 | N23: =IF(H23>0,G23+H23-I23-J23-K23-L23-M23,G23-I23-J23-K23-L23-M23) -> 60000 | O23: =G23+H23-J23-I23-K23-L23-M23 -> 60000 | P23: =IF(G23+H23<0,0,G23+H23) -> 60000 | Q23: 45660 | S23: 45632 | V23: MERCADO PAGO | X23: 7 | Y23: 7 | Z23: =IF(N23<0,0,N23) -> 60000 | AH23: 1 | AI23: =IF(F23<=6,15,25) -> 25 | AJ23: =IF(O23<>0,25,15) -> 25 | AK23: =IF(AI23-T23=24,1,0) -> 0 | AL23: =IF(AH23-AK23=AH23,0,AH23) -> 0 | AM23: =IF(AK23<>0,U23,0) -> 0 | AN23: =IF(AK23=1,O23,0) -> 0 | AO23: =IF(AI23-T23=14,1,0) -> 0 | AP23: =IF(AH23-AO23=AH23,0,AH23) -> 0 | AQ23: =IF(AO23<>0,U23,0) -> 0 | AR23: =IF(AO23=1,O23,0) -> 0 | AS23: =IF(SUM(I23:M23)<>0,1,0) -> 0 | AT23: =AS23 -> 0 | AU23: =IF(O23>0,1,0) -> 1 | AV23: =IF(AK23+AO23+AU23=1,AU23,0) -> 1 | AW23: =IF(AI23-AV23=24,1,0) -> 1 | AX23: =IF(AH23-AW23=AH23,0,AH23) -> 1 | AY23: =IF(AW23=1,O23,0) -> 60000 | AZ23: =IF(AY23-BA23<>0,AY23,0) -> 60000 | BA23: =IF(AY23<0,AY23,0) -> 0 | BB23: =IF(AI23-AV23=14,1,0) -> 0 | BC23: =IF(AH23-BB23=AH23,0,AH23) -> 0 | BD23: =IF(BB23=1,O23,0) -> 0 | BE23: =IF(BD23<0,BD23,0) -> 0 | BF23: =IF(BD23-BE23<>0,BD23,0) -> 0
A24: 1647 | B24: CARRIZO VANESA BERNARDINA | C24: 264-6241000 | D24: ZONDA | E24: 9624 | F24: 54 | G24: 30000 | H24: 0 | N24: =IF(H24>0,G24+H24-I24-J24-K24-L24-M24,G24-I24-J24-K24-L24-M24) -> 30000 | O24: =G24+H24-J24-I24-K24-L24-M24 -> 30000 | P24: =IF(G24+H24<0,0,G24+H24) -> 30000 | S24: 45654 | X24: 7 | Y24: 7 | Z24: =IF(N24<0,0,N24) -> 30000 | AH24: 1 | AI24: =IF(F24<=6,15,25) -> 25 | AJ24: =IF(O24<>0,25,15) -> 25 | AK24: =IF(AI24-T24=24,1,0) -> 0 | AL24: =IF(AH24-AK24=AH24,0,AH24) -> 0 | AM24: =IF(AK24<>0,U24,0) -> 0 | AN24: =IF(AK24=1,O24,0) -> 0 | AO24: =IF(AI24-T24=14,1,0) -> 0 | AP24: =IF(AH24-AO24=AH24,0,AH24) -> 0 | AQ24: =IF(AO24<>0,U24,0) -> 0 | AR24: =IF(AO24=1,O24,0) -> 0 | AS24: =IF(SUM(I24:M24)<>0,1,0) -> 0 | AT24: =AS24 -> 0 | AU24: =IF(O24>0,1,0) -> 1 | AV24: =IF(AK24+AO24+AU24=1,AU24,0) -> 1 | AW24: =IF(AI24-AV24=24,1,0) -> 1 | AX24: =IF(AH24-AW24=AH24,0,AH24) -> 1 | AY24: =IF(AW24=1,O24,0) -> 30000 | AZ24: =IF(AY24-BA24<>0,AY24,0) -> 30000 | BA24: =IF(AY24<0,AY24,0) -> 0 | BB24: =IF(AI24-AV24=14,1,0) -> 0 | BC24: =IF(AH24-BB24=AH24,0,AH24) -> 0 | BD24: =IF(BB24=1,O24,0) -> 0 | BE24: =IF(BD24<0,BD24,0) -> 0 | BF24: =IF(BD24-BE24<>0,BD24,0) -> 0
A25: 1671 | B25: TRIGO ESPEJO CARLOS JAVIER | C25: 264-5789951 | D25: RAWSON | E25: 9740 | F25: 54 | G25: 30000 | H25: -32000 | N25: =IF(H25>0,G25+H25-I25-J25-K25-L25-M25,G25-I25-J25-K25-L25-M25) -> 30000 | O25: =G25+H25-J25-I25-K25-L25-M25 -> -2000 | P25: =IF(G25+H25<0,0,G25+H25) -> 0 | S25: 45656 | X25: 7 | Y25: 7 | Z25: =IF(N25<0,0,N25) -> 30000 | AH25: 1 | AI25: =IF(F25<=6,15,25) -> 25 | AJ25: =IF(O25<>0,25,15) -> 25 | AK25: =IF(AI25-T25=24,1,0) -> 0 | AL25: =IF(AH25-AK25=AH25,0,AH25) -> 0 | AM25: =IF(AK25<>0,U25,0) -> 0 | AN25: =IF(AK25=1,O25,0) -> 0 | AO25: =IF(AI25-T25=14,1,0) -> 0 | AP25: =IF(AH25-AO25=AH25,0,AH25) -> 0 | AQ25: =IF(AO25<>0,U25,0) -> 0 | AR25: =IF(AO25=1,O25,0) -> 0 | AS25: =IF(SUM(I25:M25)<>0,1,0) -> 0 | AT25: =AS25 -> 0 | AU25: =IF(O25>0,1,0) -> 0 | AV25: =IF(AK25+AO25+AU25=1,AU25,0) -> 0 | AW25: =IF(AI25-AV25=24,1,0) -> 0 | AX25: =IF(AH25-AW25=AH25,0,AH25) -> 0 | AY25: =IF(AW25=1,O25,0) -> 0 | AZ25: =IF(AY25-BA25<>0,AY25,0) -> 0 | BA25: =IF(AY25<0,AY25,0) -> 0 | BB25: =IF(AI25-AV25=14,1,0) -> 0 | BC25: =IF(AH25-BB25=AH25,0,AH25) -> 0 | BD25: =IF(BB25=1,O25,0) -> 0 | BE25: =IF(BD25<0,BD25,0) -> 0 | BF25: =IF(BD25-BE25<>0,BD25,0) -> 0
A26: 1673 | B26: ROBLEDO NELIDA LOURDES | C26: 264-4428110 | D26: SAN JUAN | E26: 9762 | F26: 54 | G26: 60000 | H26: -145000 | N26: =IF(H26>0,G26+H26-I26-J26-K26-L26-M26,G26-I26-J26-K26-L26-M26) -> 60000 | O26: =G26+H26-J26-I26-K26-L26-M26 -> -85000 | P26: =IF(G26+H26<0,0,G26+H26) -> 0 | S26: 45635 | X26: 7 | Y26: 7 | Z26: =IF(N26<0,0,N26) -> 60000 | AH26: 1 | AI26: =IF(F26<=6,15,25) -> 25 | AJ26: =IF(O26<>0,25,15) -> 25 | AK26: =IF(AI26-T26=24,1,0) -> 0 | AL26: =IF(AH26-AK26=AH26,0,AH26) -> 0 | AM26: =IF(AK26<>0,U26,0) -> 0 | AN26: =IF(AK26=1,O26,0) -> 0 | AO26: =IF(AI26-T26=14,1,0) -> 0 | AP26: =IF(AH26-AO26=AH26,0,AH26) -> 0 | AQ26: =IF(AO26<>0,U26,0) -> 0 | AR26: =IF(AO26=1,O26,0) -> 0 | AS26: =IF(SUM(I26:M26)<>0,1,0) -> 0 | AT26: =AS26 -> 0 | AU26: =IF(O26>0,1,0) -> 0 | AV26: =IF(AK26+AO26+AU26=1,AU26,0) -> 0 | AW26: =IF(AI26-AV26=24,1,0) -> 0 | AX26: =IF(AH26-AW26=AH26,0,AH26) -> 0 | AY26: =IF(AW26=1,O26,0) -> 0 | AZ26: =IF(AY26-BA26<>0,AY26,0) -> 0 | BA26: =IF(AY26<0,AY26,0) -> 0 | BB26: =IF(AI26-AV26=14,1,0) -> 0 | BC26: =IF(AH26-BB26=AH26,0,AH26) -> 0 | BD26: =IF(BB26=1,O26,0) -> 0 | BE26: =IF(BD26<0,BD26,0) -> 0 | BF26: =IF(BD26-BE26<>0,BD26,0) -> 0
A27: 1762 | B27: AZCURRA RUBEN ISAAC | C27: 261-2530350 | D27: RAWSON | E27: 9816 | F27: 52 | G27: 55000 | H27: -29700 | N27: =IF(H27>0,G27+H27-I27-J27-K27-L27-M27,G27-I27-J27-K27-L27-M27) -> 55000 | O27: =G27+H27-J27-I27-K27-L27-M27 -> 25300 | P27: =IF(G27+H27<0,0,G27+H27) -> 25300 | S27: 45632 | X27: 7 | Y27: 7 | Z27: =IF(N27<0,0,N27) -> 55000 | AH27: 1 | AI27: =IF(F27<=6,15,25) -> 25 | AJ27: =IF(O27<>0,25,15) -> 25 | AK27: =IF(AI27-T27=24,1,0) -> 0 | AL27: =IF(AH27-AK27=AH27,0,AH27) -> 0 | AM27: =IF(AK27<>0,U27,0) -> 0 | AN27: =IF(AK27=1,O27,0) -> 0 | AO27: =IF(AI27-T27=14,1,0) -> 0 | AP27: =IF(AH27-AO27=AH27,0,AH27) -> 0 | AQ27: =IF(AO27<>0,U27,0) -> 0 | AR27: =IF(AO27=1,O27,0) -> 0 | AS27: =IF(SUM(I27:M27)<>0,1,0) -> 0 | AT27: =AS27 -> 0 | AU27: =IF(O27>0,1,0) -> 1 | AV27: =IF(AK27+AO27+AU27=1,AU27,0) -> 1 | AW27: =IF(AI27-AV27=24,1,0) -> 1 | AX27: =IF(AH27-AW27=AH27,0,AH27) -> 1 | AY27: =IF(AW27=1,O27,0) -> 25300 | AZ27: =IF(AY27-BA27<>0,AY27,0) -> 25300 | BA27: =IF(AY27<0,AY27,0) -> 0 | BB27: =IF(AI27-AV27=14,1,0) -> 0 | BC27: =IF(AH27-BB27=AH27,0,AH27) -> 0 | BD27: =IF(BB27=1,O27,0) -> 0 | BE27: =IF(BD27<0,BD27,0) -> 0 | BF27: =IF(BD27-BE27<>0,BD27,0) -> 0
A28: 1791 | B28: MUÑOZ ALICIA ADRIANA | C28: 264-4700323 | D28: CHIMBAS | E28: 9908 | F28: 52 | G28: 60000 | H28: -15000 | N28: =IF(H28>0,G28+H28-I28-J28-K28-L28-M28,G28-I28-J28-K28-L28-M28) -> 60000 | O28: =G28+H28-J28-I28-K28-L28-M28 -> 45000 | P28: =IF(G28+H28<0,0,G28+H28) -> 45000 | S28: 45642 | X28: 7 | Y28: 7 | Z28: =IF(N28<0,0,N28) -> 60000 | AH28: 1 | AI28: =IF(F28<=6,15,25) -> 25 | AJ28: =IF(O28<>0,25,15) -> 25 | AK28: =IF(AI28-T28=24,1,0) -> 0 | AL28: =IF(AH28-AK28=AH28,0,AH28) -> 0 | AM28: =IF(AK28<>0,U28,0) -> 0 | AN28: =IF(AK28=1,O28,0) -> 0 | AO28: =IF(AI28-T28=14,1,0) -> 0 | AP28: =IF(AH28-AO28=AH28,0,AH28) -> 0 | AQ28: =IF(AO28<>0,U28,0) -> 0 | AR28: =IF(AO28=1,O28,0) -> 0 | AS28: =IF(SUM(I28:M28)<>0,1,0) -> 0 | AT28: =AS28 -> 0 | AU28: =IF(O28>0,1,0) -> 1 | AV28: =IF(AK28+AO28+AU28=1,AU28,0) -> 1 | AW28: =IF(AI28-AV28=24,1,0) -> 1 | AX28: =IF(AH28-AW28=AH28,0,AH28) -> 1 | AY28: =IF(AW28=1,O28,0) -> 45000 | AZ28: =IF(AY28-BA28<>0,AY28,0) -> 45000 | BA28: =IF(AY28<0,AY28,0) -> 0 | BB28: =IF(AI28-AV28=14,1,0) -> 0 | BC28: =IF(AH28-BB28=AH28,0,AH28) -> 0 | BD28: =IF(BB28=1,O28,0) -> 0 | BE28: =IF(BD28<0,BD28,0) -> 0 | BF28: =IF(BD28-BE28<>0,BD28,0) -> 0
A29: 1829 | B29: MANRIQUE BRIZUELA BARBARA ELIZABETH | C29: 264-6611493 | D29: JACHAL | E29: 9936 | F29: 51 | G29: 30000 | H29: -5000 | N29: =IF(H29>0,G29+H29-I29-J29-K29-L29-M29,G29-I29-J29-K29-L29-M29) -> 30000 | O29: =G29+H29-J29-I29-K29-L29-M29 -> 25000 | P29: =IF(G29+H29<0,0,G29+H29) -> 25000 | S29: 45638 | X29: 7 | Y29: 7 | Z29: =IF(N29<0,0,N29) -> 30000 | AH29: 1 | AI29: =IF(F29<=6,15,25) -> 25 | AJ29: =IF(O29<>0,25,15) -> 25 | AK29: =IF(AI29-T29=24,1,0) -> 0 | AL29: =IF(AH29-AK29=AH29,0,AH29) -> 0 | AM29: =IF(AK29<>0,U29,0) -> 0 | AN29: =IF(AK29=1,O29,0) -> 0 | AO29: =IF(AI29-T29=14,1,0) -> 0 | AP29: =IF(AH29-AO29=AH29,0,AH29) -> 0 | AQ29: =IF(AO29<>0,U29,0) -> 0 | AR29: =IF(AO29=1,O29,0) -> 0 | AS29: =IF(SUM(I29:M29)<>0,1,0) -> 0 | AT29: =AS29 -> 0 | AU29: =IF(O29>0,1,0) -> 1 | AV29: =IF(AK29+AO29+AU29=1,AU29,0) -> 1 | AW29: =IF(AI29-AV29=24,1,0) -> 1 | AX29: =IF(AH29-AW29=AH29,0,AH29) -> 1 | AY29: =IF(AW29=1,O29,0) -> 25000 | AZ29: =IF(AY29-BA29<>0,AY29,0) -> 25000 | BA29: =IF(AY29<0,AY29,0) -> 0 | BB29: =IF(AI29-AV29=14,1,0) -> 0 | BC29: =IF(AH29-BB29=AH29,0,AH29) -> 0 | BD29: =IF(BB29=1,O29,0) -> 0 | BE29: =IF(BD29<0,BD29,0) -> 0 | BF29: =IF(BD29-BE29<>0,BD29,0) -> 0
A30: 1870 | B30: OCHOA ERICA DEBORA | C30: 264-5178841 | D30: SAN JUAN | E30: 9889 | F30: 50 | G30: 40000 | H30: 0 | N30: =IF(H30>0,G30+H30-I30-J30-K30-L30-M30,G30-I30-J30-K30-L30-M30) -> 40000 | O30: =G30+H30-J30-I30-K30-L30-M30 -> 40000 | P30: =IF(G30+H30<0,0,G30+H30) -> 40000 | S30: 45632 | X30: 7 | Y30: 7 | Z30: =IF(N30<0,0,N30) -> 40000 | AH30: 1 | AI30: =IF(F30<=6,15,25) -> 25 | AJ30: =IF(O30<>0,25,15) -> 25 | AK30: =IF(AI30-T30=24,1,0) -> 0 | AL30: =IF(AH30-AK30=AH30,0,AH30) -> 0 | AM30: =IF(AK30<>0,U30,0) -> 0 | AN30: =IF(AK30=1,O30,0) -> 0 | AO30: =IF(AI30-T30=14,1,0) -> 0 | AP30: =IF(AH30-AO30=AH30,0,AH30) -> 0 | AQ30: =IF(AO30<>0,U30,0) -> 0 | AR30: =IF(AO30=1,O30,0) -> 0 | AS30: =IF(SUM(I30:M30)<>0,1,0) -> 0 | AT30: =AS30 -> 0 | AU30: =IF(O30>0,1,0) -> 1 | AV30: =IF(AK30+AO30+AU30=1,AU30,0) -> 1 | AW30: =IF(AI30-AV30=24,1,0) -> 1 | AX30: =IF(AH30-AW30=AH30,0,AH30) -> 1 | AY30: =IF(AW30=1,O30,0) -> 40000 | AZ30: =IF(AY30-BA30<>0,AY30,0) -> 40000 | BA30: =IF(AY30<0,AY30,0) -> 0 | BB30: =IF(AI30-AV30=14,1,0) -> 0 | BC30: =IF(AH30-BB30=AH30,0,AH30) -> 0 | BD30: =IF(BB30=1,O30,0) -> 0 | BE30: =IF(BD30<0,BD30,0) -> 0 | BF30: =IF(BD30-BE30<>0,BD30,0) -> 0
A31: 1871 | B31: FERNANDEZ GORIA GABRIELA CELESTE | C31: 264-5676031 | D31: RIVADAVIA | E31: 9891 | F31: 50 | G31: 35000 | H31: 0 | N31: =IF(H31>0,G31+H31-I31-J31-K31-L31-M31,G31-I31-J31-K31-L31-M31) -> 35000 | O31: =G31+H31-J31-I31-K31-L31-M31 -> 35000 | P31: =IF(G31+H31<0,0,G31+H31) -> 35000 | S31: 45649 | X31: 7 | Y31: 7 | Z31: =IF(N31<0,0,N31) -> 35000 | AH31: 1 | AI31: =IF(F31<=6,15,25) -> 25 | AJ31: =IF(O31<>0,25,15) -> 25 | AK31: =IF(AI31-T31=24,1,0) -> 0 | AL31: =IF(AH31-AK31=AH31,0,AH31) -> 0 | AM31: =IF(AK31<>0,U31,0) -> 0 | AN31: =IF(AK31=1,O31,0) -> 0 | AO31: =IF(AI31-T31=14,1,0) -> 0 | AP31: =IF(AH31-AO31=AH31,0,AH31) -> 0 | AQ31: =IF(AO31<>0,U31,0) -> 0 | AR31: =IF(AO31=1,O31,0) -> 0 | AS31: =IF(SUM(I31:M31)<>0,1,0) -> 0 | AT31: =AS31 -> 0 | AU31: =IF(O31>0,1,0) -> 1 | AV31: =IF(AK31+AO31+AU31=1,AU31,0) -> 1 | AW31: =IF(AI31-AV31=24,1,0) -> 1 | AX31: =IF(AH31-AW31=AH31,0,AH31) -> 1 | AY31: =IF(AW31=1,O31,0) -> 35000 | AZ31: =IF(AY31-BA31<>0,AY31,0) -> 35000 | BA31: =IF(AY31<0,AY31,0) -> 0 | BB31: =IF(AI31-AV31=14,1,0) -> 0 | BC31: =IF(AH31-BB31=AH31,0,AH31) -> 0 | BD31: =IF(BB31=1,O31,0) -> 0 | BE31: =IF(BD31<0,BD31,0) -> 0 | BF31: =IF(BD31-BE31<>0,BD31,0) -> 0
A32: 1884 | B32: CEPEDA MANUEL ALFREDO | C32: 264-5252064 | D32: CAUCETE | E32: 9959 | F32: 50 | G32: 55000 | H32: -25500 | N32: =IF(H32>0,G32+H32-I32-J32-K32-L32-M32,G32-I32-J32-K32-L32-M32) -> 55000 | O32: =G32+H32-J32-I32-K32-L32-M32 -> 29500 | P32: =IF(G32+H32<0,0,G32+H32) -> 29500 | Q32: 45659 | S32: 45635 | V32: MERCADO PAGO | X32: 7 | Y32: 7 | Z32: =IF(N32<0,0,N32) -> 55000 | AH32: 1 | AI32: =IF(F32<=6,15,25) -> 25 | AJ32: =IF(O32<>0,25,15) -> 25 | AK32: =IF(AI32-T32=24,1,0) -> 0 | AL32: =IF(AH32-AK32=AH32,0,AH32) -> 0 | AM32: =IF(AK32<>0,U32,0) -> 0 | AN32: =IF(AK32=1,O32,0) -> 0 | AO32: =IF(AI32-T32=14,1,0) -> 0 | AP32: =IF(AH32-AO32=AH32,0,AH32) -> 0 | AQ32: =IF(AO32<>0,U32,0) -> 0 | AR32: =IF(AO32=1,O32,0) -> 0 | AS32: =IF(SUM(I32:M32)<>0,1,0) -> 0 | AT32: =AS32 -> 0 | AU32: =IF(O32>0,1,0) -> 1 | AV32: =IF(AK32+AO32+AU32=1,AU32,0) -> 1 | AW32: =IF(AI32-AV32=24,1,0) -> 1 | AX32: =IF(AH32-AW32=AH32,0,AH32) -> 1 | AY32: =IF(AW32=1,O32,0) -> 29500 | AZ32: =IF(AY32-BA32<>0,AY32,0) -> 29500 | BA32: =IF(AY32<0,AY32,0) -> 0 | BB32: =IF(AI32-AV32=14,1,0) -> 0 | BC32: =IF(AH32-BB32=AH32,0,AH32) -> 0 | BD32: =IF(BB32=1,O32,0) -> 0 | BE32: =IF(BD32<0,BD32,0) -> 0 | BF32: =IF(BD32-BE32<>0,BD32,0) -> 0
A33: 1900 | B33: CERDA FABIAN ALEJANDRO | C33: 264-6621777 | D33: CHIMBAS | E33: 10012 | F33: 50 | G33: 60000 | H33: -50000 | N33: =IF(H33>0,G33+H33-I33-J33-K33-L33-M33,G33-I33-J33-K33-L33-M33) -> 60000 | O33: =G33+H33-J33-I33-K33-L33-M33 -> 10000 | P33: =IF(G33+H33<0,0,G33+H33) -> 10000 | S33: 45656 | X33: 7 | Y33: 7 | Z33: =IF(N33<0,0,N33) -> 60000 | AH33: 1 | AI33: =IF(F33<=6,15,25) -> 25 | AJ33: =IF(O33<>0,25,15) -> 25 | AK33: =IF(AI33-T33=24,1,0) -> 0 | AL33: =IF(AH33-AK33=AH33,0,AH33) -> 0 | AM33: =IF(AK33<>0,U33,0) -> 0 | AN33: =IF(AK33=1,O33,0) -> 0 | AO33: =IF(AI33-T33=14,1,0) -> 0 | AP33: =IF(AH33-AO33=AH33,0,AH33) -> 0 | AQ33: =IF(AO33<>0,U33,0) -> 0 | AR33: =IF(AO33=1,O33,0) -> 0 | AS33: =IF(SUM(I33:M33)<>0,1,0) -> 0 | AT33: =AS33 -> 0 | AU33: =IF(O33>0,1,0) -> 1 | AV33: =IF(AK33+AO33+AU33=1,AU33,0) -> 1 | AW33: =IF(AI33-AV33=24,1,0) -> 1 | AX33: =IF(AH33-AW33=AH33,0,AH33) -> 1 | AY33: =IF(AW33=1,O33,0) -> 10000 | AZ33: =IF(AY33-BA33<>0,AY33,0) -> 10000 | BA33: =IF(AY33<0,AY33,0) -> 0 | BB33: =IF(AI33-AV33=14,1,0) -> 0 | BC33: =IF(AH33-BB33=AH33,0,AH33) -> 0 | BD33: =IF(BB33=1,O33,0) -> 0 | BE33: =IF(BD33<0,BD33,0) -> 0 | BF33: =IF(BD33-BE33<>0,BD33,0) -> 0
A34: 1952 | B34: SALCEDO JORGE LUIS | C34: 264-6053240 | D34: CHIMBAS | E34: 10019 | F34: 48 | G34: 60000 | H34: 0 | N34: =IF(H34>0,G34+H34-I34-J34-K34-L34-M34,G34-I34-J34-K34-L34-M34) -> 60000 | O34: =G34+H34-J34-I34-K34-L34-M34 -> 60000 | P34: =IF(G34+H34<0,0,G34+H34) -> 60000 | Q34: 45663 | S34: 45633 | V34: MERCADO PAGO | X34: 7 | Y34: 7 | Z34: =IF(N34<0,0,N34) -> 60000 | AH34: 1 | AI34: =IF(F34<=6,15,25) -> 25 | AJ34: =IF(O34<>0,25,15) -> 25 | AK34: =IF(AI34-T34=24,1,0) -> 0 | AL34: =IF(AH34-AK34=AH34,0,AH34) -> 0 | AM34: =IF(AK34<>0,U34,0) -> 0 | AN34: =IF(AK34=1,O34,0) -> 0 | AO34: =IF(AI34-T34=14,1,0) -> 0 | AP34: =IF(AH34-AO34=AH34,0,AH34) -> 0 | AQ34: =IF(AO34<>0,U34,0) -> 0 | AR34: =IF(AO34=1,O34,0) -> 0 | AS34: =IF(SUM(I34:M34)<>0,1,0) -> 0 | AT34: =AS34 -> 0 | AU34: =IF(O34>0,1,0) -> 1 | AV34: =IF(AK34+AO34+AU34=1,AU34,0) -> 1 | AW34: =IF(AI34-AV34=24,1,0) -> 1 | AX34: =IF(AH34-AW34=AH34,0,AH34) -> 1 | AY34: =IF(AW34=1,O34,0) -> 60000 | AZ34: =IF(AY34-BA34<>0,AY34,0) -> 60000 | BA34: =IF(AY34<0,AY34,0) -> 0 | BB34: =IF(AI34-AV34=14,1,0) -> 0 | BC34: =IF(AH34-BB34=AH34,0,AH34) -> 0 | BD34: =IF(BB34=1,O34,0) -> 0 | BE34: =IF(BD34<0,BD34,0) -> 0 | BF34: =IF(BD34-BE34<>0,BD34,0) -> 0
A35: 1954 | B35: GUTIERREZ ATENCIO ELDA VANESA | C35: 264-4580614 | D35: ZONDA | E35: 10045 | F35: 48 | G35: 50000 | H35: -30000 | N35: =IF(H35>0,G35+H35-I35-J35-K35-L35-M35,G35-I35-J35-K35-L35-M35) -> 50000 | O35: =G35+H35-J35-I35-K35-L35-M35 -> 20000 | P35: =IF(G35+H35<0,0,G35+H35) -> 20000 | Q35: 45659 | S35: 45628 | V35: MERCADO PAGO | X35: 7 | Y35: 7 | Z35: =IF(N35<0,0,N35) -> 50000 | AH35: 1 | AI35: =IF(F35<=6,15,25) -> 25 | AJ35: =IF(O35<>0,25,15) -> 25 | AK35: =IF(AI35-T35=24,1,0) -> 0 | AL35: =IF(AH35-AK35=AH35,0,AH35) -> 0 | AM35: =IF(AK35<>0,U35,0) -> 0 | AN35: =IF(AK35=1,O35,0) -> 0 | AO35: =IF(AI35-T35=14,1,0) -> 0 | AP35: =IF(AH35-AO35=AH35,0,AH35) -> 0 | AQ35: =IF(AO35<>0,U35,0) -> 0 | AR35: =IF(AO35=1,O35,0) -> 0 | AS35: =IF(SUM(I35:M35)<>0,1,0) -> 0 | AT35: =AS35 -> 0 | AU35: =IF(O35>0,1,0) -> 1 | AV35: =IF(AK35+AO35+AU35=1,AU35,0) -> 1 | AW35: =IF(AI35-AV35=24,1,0) -> 1 | AX35: =IF(AH35-AW35=AH35,0,AH35) -> 1 | AY35: =IF(AW35=1,O35,0) -> 20000 | AZ35: =IF(AY35-BA35<>0,AY35,0) -> 20000 | BA35: =IF(AY35<0,AY35,0) -> 0 | BB35: =IF(AI35-AV35=14,1,0) -> 0 | BC35: =IF(AH35-BB35=AH35,0,AH35) -> 0 | BD35: =IF(BB35=1,O35,0) -> 0 | BE35: =IF(BD35<0,BD35,0) -> 0 | BF35: =IF(BD35-BE35<>0,BD35,0) -> 0
A36: 1956 | B36: SUAREZ BEATRIZ CAROLINA | C36: 011-62747711 | D36: AVELLANEDA | E36: 10057 | F36: 48 | G36: 35000 | H36: -57000 | N36: =IF(H36>0,G36+H36-I36-J36-K36-L36-M36,G36-I36-J36-K36-L36-M36) -> 35000 | O36: =G36+H36-J36-I36-K36-L36-M36 -> -22000 | P36: =IF(G36+H36<0,0,G36+H36) -> 0 | S36: 45638 | X36: 7 | Y36: 7 | Z36: =IF(N36<0,0,N36) -> 35000 | AH36: 1 | AI36: =IF(F36<=6,15,25) -> 25 | AJ36: =IF(O36<>0,25,15) -> 25 | AK36: =IF(AI36-T36=24,1,0) -> 0 | AL36: =IF(AH36-AK36=AH36,0,AH36) -> 0 | AM36: =IF(AK36<>0,U36,0) -> 0 | AN36: =IF(AK36=1,O36,0) -> 0 | AO36: =IF(AI36-T36=14,1,0) -> 0 | AP36: =IF(AH36-AO36=AH36,0,AH36) -> 0 | AQ36: =IF(AO36<>0,U36,0) -> 0 | AR36: =IF(AO36=1,O36,0) -> 0 | AS36: =IF(SUM(I36:M36)<>0,1,0) -> 0 | AT36: =AS36 -> 0 | AU36: =IF(O36>0,1,0) -> 0 | AV36: =IF(AK36+AO36+AU36=1,AU36,0) -> 0 | AW36: =IF(AI36-AV36=24,1,0) -> 0 | AX36: =IF(AH36-AW36=AH36,0,AH36) -> 0 | AY36: =IF(AW36=1,O36,0) -> 0 | AZ36: =IF(AY36-BA36<>0,AY36,0) -> 0 | BA36: =IF(AY36<0,AY36,0) -> 0 | BB36: =IF(AI36-AV36=14,1,0) -> 0 | BC36: =IF(AH36-BB36=AH36,0,AH36) -> 0 | BD36: =IF(BB36=1,O36,0) -> 0 | BE36: =IF(BD36<0,BD36,0) -> 0 | BF36: =IF(BD36-BE36<>0,BD36,0) -> 0
A37: 1999 | B37: PEREZ JOSE ISMAEL | C37: 264-5122570 | D37: SAN JUAN | E37: 10192 | F37: 47 | G37: 60000 | H37: -15000 | N37: =IF(H37>0,G37+H37-I37-J37-K37-L37-M37,G37-I37-J37-K37-L37-M37) -> 60000 | O37: =G37+H37-J37-I37-K37-L37-M37 -> 45000 | P37: =IF(G37+H37<0,0,G37+H37) -> 45000 | Q37: 45660 | S37: 45628 | V37: MERCADO PAGO | X37: 7 | Y37: 7 | Z37: =IF(N37<0,0,N37) -> 60000 | AH37: 1 | AI37: =IF(F37<=6,15,25) -> 25 | AJ37: =IF(O37<>0,25,15) -> 25 | AK37: =IF(AI37-T37=24,1,0) -> 0 | AL37: =IF(AH37-AK37=AH37,0,AH37) -> 0 | AM37: =IF(AK37<>0,U37,0) -> 0 | AN37: =IF(AK37=1,O37,0) -> 0 | AO37: =IF(AI37-T37=14,1,0) -> 0 | AP37: =IF(AH37-AO37=AH37,0,AH37) -> 0 | AQ37: =IF(AO37<>0,U37,0) -> 0 | AR37: =IF(AO37=1,O37,0) -> 0 | AS37: =IF(SUM(I37:M37)<>0,1,0) -> 0 | AT37: =AS37 -> 0 | AU37: =IF(O37>0,1,0) -> 1 | AV37: =IF(AK37+AO37+AU37=1,AU37,0) -> 1 | AW37: =IF(AI37-AV37=24,1,0) -> 1 | AX37: =IF(AH37-AW37=AH37,0,AH37) -> 1 | AY37: =IF(AW37=1,O37,0) -> 45000 | AZ37: =IF(AY37-BA37<>0,AY37,0) -> 45000 | BA37: =IF(AY37<0,AY37,0) -> 0 | BB37: =IF(AI37-AV37=14,1,0) -> 0 | BC37: =IF(AH37-BB37=AH37,0,AH37) -> 0 | BD37: =IF(BB37=1,O37,0) -> 0 | BE37: =IF(BD37<0,BD37,0) -> 0 | BF37: =IF(BD37-BE37<>0,BD37,0) -> 0
A38: 2007 | B38: SEVILLA MAXIMILIANO ALFREDO | C38: 264-4992333 | D38: SAN JUAN | E38: 10202 | F38: 47 | G38: 45000 | H38: 0 | N38: =IF(H38>0,G38+H38-I38-J38-K38-L38-M38,G38-I38-J38-K38-L38-M38) -> 45000 | O38: =G38+H38-J38-I38-K38-L38-M38 -> 45000 | P38: =IF(G38+H38<0,0,G38+H38) -> 45000 | Q38: 45663 | S38: 45630 | V38: MERCADO PAGO | X38: 7 | Y38: 7 | Z38: =IF(N38<0,0,N38) -> 45000 | AH38: 1 | AI38: =IF(F38<=6,15,25) -> 25 | AJ38: =IF(O38<>0,25,15) -> 25 | AK38: =IF(AI38-T38=24,1,0) -> 0 | AL38: =IF(AH38-AK38=AH38,0,AH38) -> 0 | AM38: =IF(AK38<>0,U38,0) -> 0 | AN38: =IF(AK38=1,O38,0) -> 0 | AO38: =IF(AI38-T38=14,1,0) -> 0 | AP38: =IF(AH38-AO38=AH38,0,AH38) -> 0 | AQ38: =IF(AO38<>0,U38,0) -> 0 | AR38: =IF(AO38=1,O38,0) -> 0 | AS38: =IF(SUM(I38:M38)<>0,1,0) -> 0 | AT38: =AS38 -> 0 | AU38: =IF(O38>0,1,0) -> 1 | AV38: =IF(AK38+AO38+AU38=1,AU38,0) -> 1 | AW38: =IF(AI38-AV38=24,1,0) -> 1 | AX38: =IF(AH38-AW38=AH38,0,AH38) -> 1 | AY38: =IF(AW38=1,O38,0) -> 45000 | AZ38: =IF(AY38-BA38<>0,AY38,0) -> 45000 | BA38: =IF(AY38<0,AY38,0) -> 0 | BB38: =IF(AI38-AV38=14,1,0) -> 0 | BC38: =IF(AH38-BB38=AH38,0,AH38) -> 0 | BD38: =IF(BB38=1,O38,0) -> 0 | BE38: =IF(BD38<0,BD38,0) -> 0 | BF38: =IF(BD38-BE38<>0,BD38,0) -> 0
A39: 2010 | B39: PEREYRA NUVIA CELESTE | C39: 264-4829505 | D39: SANTA LUCIA | E39: 10206 | F39: 47 | G39: 30000 | H39: -28000 | N39: =IF(H39>0,G39+H39-I39-J39-K39-L39-M39,G39-I39-J39-K39-L39-M39) -> 30000 | O39: =G39+H39-J39-I39-K39-L39-M39 -> 2000 | P39: =IF(G39+H39<0,0,G39+H39) -> 2000 | S39: 45647 | X39: 7 | Y39: 7 | Z39: =IF(N39<0,0,N39) -> 30000 | AH39: 1 | AI39: =IF(F39<=6,15,25) -> 25 | AJ39: =IF(O39<>0,25,15) -> 25 | AK39: =IF(AI39-T39=24,1,0) -> 0 | AL39: =IF(AH39-AK39=AH39,0,AH39) -> 0 | AM39: =IF(AK39<>0,U39,0) -> 0 | AN39: =IF(AK39=1,O39,0) -> 0 | AO39: =IF(AI39-T39=14,1,0) -> 0 | AP39: =IF(AH39-AO39=AH39,0,AH39) -> 0 | AQ39: =IF(AO39<>0,U39,0) -> 0 | AR39: =IF(AO39=1,O39,0) -> 0 | AS39: =IF(SUM(I39:M39)<>0,1,0) -> 0 | AT39: =AS39 -> 0 | AU39: =IF(O39>0,1,0) -> 1 | AV39: =IF(AK39+AO39+AU39=1,AU39,0) -> 1 | AW39: =IF(AI39-AV39=24,1,0) -> 1 | AX39: =IF(AH39-AW39=AH39,0,AH39) -> 1 | AY39: =IF(AW39=1,O39,0) -> 2000 | AZ39: =IF(AY39-BA39<>0,AY39,0) -> 2000 | BA39: =IF(AY39<0,AY39,0) -> 0 | BB39: =IF(AI39-AV39=14,1,0) -> 0 | BC39: =IF(AH39-BB39=AH39,0,AH39) -> 0 | BD39: =IF(BB39=1,O39,0) -> 0 | BE39: =IF(BD39<0,BD39,0) -> 0 | BF39: =IF(BD39-BE39<>0,BD39,0) -> 0
A40: 2015 | B40: ELIZONDO MARIO SANTIAGO | C40: 264-5061888 | D40: ALBARDON | E40: 10189 | F40: 47 | G40: 70000 | H40: -118000 | N40: =IF(H40>0,G40+H40-I40-J40-K40-L40-M40,G40-I40-J40-K40-L40-M40) -> 70000 | O40: =G40+H40-J40-I40-K40-L40-M40 -> -48000 | P40: =IF(G40+H40<0,0,G40+H40) -> 0 | Q40: 45663 | S40: 45629 | V40: MERCADO PAGO | X40: 7 | Y40: 7 | Z40: =IF(N40<0,0,N40) -> 70000 | AH40: 1 | AI40: =IF(F40<=6,15,25) -> 25 | AJ40: =IF(O40<>0,25,15) -> 25 | AK40: =IF(AI40-T40=24,1,0) -> 0 | AL40: =IF(AH40-AK40=AH40,0,AH40) -> 0 | AM40: =IF(AK40<>0,U40,0) -> 0 | AN40: =IF(AK40=1,O40,0) -> 0 | AO40: =IF(AI40-T40=14,1,0) -> 0 | AP40: =IF(AH40-AO40=AH40,0,AH40) -> 0 | AQ40: =IF(AO40<>0,U40,0) -> 0 | AR40: =IF(AO40=1,O40,0) -> 0 | AS40: =IF(SUM(I40:M40)<>0,1,0) -> 0 | AT40: =AS40 -> 0 | AU40: =IF(O40>0,1,0) -> 0 | AV40: =IF(AK40+AO40+AU40=1,AU40,0) -> 0 | AW40: =IF(AI40-AV40=24,1,0) -> 0 | AX40: =IF(AH40-AW40=AH40,0,AH40) -> 0 | AY40: =IF(AW40=1,O40,0) -> 0 | AZ40: =IF(AY40-BA40<>0,AY40,0) -> 0 | BA40: =IF(AY40<0,AY40,0) -> 0 | BB40: =IF(AI40-AV40=14,1,0) -> 0 | BC40: =IF(AH40-BB40=AH40,0,AH40) -> 0 | BD40: =IF(BB40=1,O40,0) -> 0 | BE40: =IF(BD40<0,BD40,0) -> 0 | BF40: =IF(BD40-BE40<>0,BD40,0) -> 0
...

Sheet COBRANZA SIN CUPONES
A1: COBRANZA SIN CUPONES
H2: PAGOS
H3: AUTOHOGAR
A4: COD | B4: CLIENTE | C4: TELEFONO | D4: LOCALIDAD | E4: SOLI | F4: N°CUOTA | G4: VALOR CUOTA | H4: PAGO | I4: PAGO X ADEL | J4: TOTAL | K4: COMISION | L4: A RENDIR | M4: N° COBRADOR | N4: OBSERVACIONES
J5: =H5+I5 -> 0 | K5: =J5*AUTOHOGAR!$M$471% -> 0 | L5: =J5-K5 -> 0
J6: =H6+I6 -> 0 | K6: =J6*AUTOHOGAR!$M$471% -> 0 | L6: =J6-K6 -> 0
J7: =H7+I7 -> 0 | K7: =J7*AUTOHOGAR!$M$471% -> 0 | L7: =J7-K7 -> 0
J8: =H8+I8 -> 0 | K8: =J8*AUTOHOGAR!$M$471% -> 0 | L8: =J8-K8 -> 0
J9: =H9+I9 -> 0 | K9: =J9*AUTOHOGAR!$M$471% -> 0 | L9: =J9-K9 -> 0
J10: =H10+I10 -> 0 | K10: =J10*AUTOHOGAR!$M$471% -> 0 | L10: =J10-K10 -> 0
J11: =H11+I11 -> 0 | K11: =J11*AUTOHOGAR!$M$471% -> 0 | L11: =J11-K11 -> 0
J12: =H12+I12 -> 0 | K12: =J12*AUTOHOGAR!$M$471% -> 0 | L12: =J12-K12 -> 0
J13: =H13+I13 -> 0 | K13: =J13*AUTOHOGAR!$M$471% -> 0 | L13: =J13-K13 -> 0
J14: =H14+I14 -> 0 | K14: =J14*AUTOHOGAR!$M$471% -> 0 | L14: =J14-K14 -> 0
J15: =H15+I15 -> 0 | K15: =J15*AUTOHOGAR!$M$471% -> 0 | L15: =J15-K15 -> 0
J16: =H16+I16 -> 0 | K16: =J16*AUTOHOGAR!$M$471% -> 0 | L16: =J16-K16 -> 0
... J24: =H24+I24 -> 0 | K24: =J24*AUTOHOGAR!$M$471% -> 0 | L24: =J24-K24 -> 0
A26: =COUNTA(A5:A24) -> 0 | H26: =SUM(H5:H25) -> 0 | I26: =SUM(I5:I25) -> 0 | J26: =SUM(J5:J25) -> 0 | K26: =SUM(K5:K25) -> 0 | L26: =SUM(L5:L25) -> 0

Sheet PAGARA
A1: CLIENTE | B1: (Todas)
A3: Etiquetas de fila | B3: Suma de CON MORA
A4: (en blanco) | B4: 476000
A5: Total general | B5: 476000

Sheet PAGARA DETALLADO
A3: Suma de CON MORA | B3: Etiquetas de columna
A4: Etiquetas de fila | B4: (en blanco) | C4: Total general
A5: ESTRELLA MICAELA DEL ROCIO | B5: 11000 | C5: 11000 | R5: 45540
A6: RAMIREZ PAULA ALEJANDRA | B6: 15000 | C6: 15000
A7: MOLINI BETINA LAURA | B7: 10000 | C7: 10000
A8: AGUILAR FIDEL CHOQUE | B8: 20000 | C8: 20000
A9: OYOLA SANCHEZ SABRINA MAILEN | B9: 4000 | C9: 4000 | M9: 30000 | Q9: 45547 | V9: GALICIA
A10: CARRIZO ALEJANDRA NELLY | B10: 9000 | C10: 9000 | R10: 45551
A11: HERRERA FRANCISCO ANTONIO | B11: 12000 | C11: 12000
A12: CARPIO NORMA ANA | B12: 7000 | C12: 7000
A13: LORENZETTI LANZILOTTA SANDRA P. | B13: 10000 | C13: 10000
A14: VARGAS MARIA HORTENCIA | B14: 6000 | C14: 6000 | R14: 45625
A15: BALMACEDA MAZA FRANCISCO EMILIO | B15: 7000 | C15: 7000 | R15: 45618
A16: CAJAS HUGO RICARDO | B16: 10000 | C16: 10000 | V16: en febro aumenta esta con un prestamo
A17: OCHOA BARBARA YAMILA | B17: 6000 | C17: 6000 | I17: 30000 | Q17: 45542
A18: ALANIZ CINTIA MACARENA | B18: 5000 | C18: 5000
A19: HEREDIA JUAN CARLOS | B19: 10000 | C19: 10000
A20: AGÜERO PATRICIO JAVIER | B20: 5000 | C20: 5000 | I20: 30000 | Q20: 45545
A21: BUSTOS NELLY MABEL | B21: 6800 | C21: 6800 | I21: 30000 | Q21: 45547 | V21: aumenta a 60.000
A22: ZAMBRA MARIA SOLEDAD | B22: 10000 | C22: 10000 | M22: 30000 | Q22: 45547 | R22: 45547
A23: GALDEANO CARRIZO HERNAN | B23: 8000 | C23: 8000
A24: PASTEN OLMOS ROSA MANUELA | B24: 4500 | C24: 4500
A25: AGUERO CARLOS MORENO | B25: 9000 | C25: 9000
A26: PUJADO LOBOS MARTIN DAVID | B26: 3000 | C26: 3000
A27: MARINERO GERMAN ANTONIO | B27: 10000 | C27: 10000
A28: MOLINA EMANUEL MARCOS JAIRO | B28: 8000 | C28: 8000 | R28: 45551 | V28: no aumenta
A29: OCAMPO BLAS RICARDO | B29: 7000 | C29: 7000
A30: MERCADO ANA BELEN | B30: 7000 | C30: 7000
A31: KENNY NOELIA VANESA | B31: 10000 | C31: 10000
A32: CAROSELLI YANINA CAROLINA | B32: 6000 | C32: 6000 | I32: 30000 | Q32: 45615 | R32: 45615 | V32: no aumenta
A33: PEREZ LUCAS SEBASTIAN | B33: 4000 | C33: 4000
A34: SALCEDO JORGE LUIS | B34: 8500 | C34: 8500
A35: NUÑEZ PAMELA GISELLE | B35: 8000 | C35: 8000
A36: GUTIERREZ ATENCIO ELDA VANESA | B36: 10000 | C36: 10000 | R36: 45551
A37: CEVALLE JORGE LEONARDO | B37: 12000 | C37: 12000 | I37: 35000 | Q37: 45615 | R37: 45615 | V37: aumenta a 55.000
A38: SILLERO GABRIELA SOLEDAD | B38: 5000 | C38: 5000
A39: NAVARRO EDUARDO AGUSTIN | B39: 15000 | C39: 15000 | V39: no aumenta
A40: RIVEROS DAYANA ESTEFANIA | B40: 10000 | C40: 10000 | R40: 45623
A41: CASTRO OSCAR ALBERTO | B41: 9700 | C41: 9700 | R41: 45617
A42: ARIA MIRTA GLADYS | B42: 5000 | C42: 5000
...

Sheet COB
A1: 1 | B1: BANCO | C1: 1
A2: 2 | B2: OFICINA SAN JUAN | C2: 3
A3: 3 | B3: REGION NOA | C3: 1
A4: 4 | B4: COBRADOR SAN JUAN | C4: 2
A5: 5 | B5: CATAMARCA | C5: 1
A6: 6 | B6: COBRADOR MENDOZA | C6: 1
A7: 7 | B7: MEDIO ELECTRONICO | C7: 1
A8: 8 | B8: GERARDO | C8: 2
A9: 9 | B9: MARTIN SAN JUAN | C9: 2
B14: BANCO O M ELECTRONICOS | C14: =COUNTIF(C1:C9,1) -> 5
B15: COBRADORES | C15: =COUNTIF(C1:C9,2) -> 3
B16: SUCURSALES | C16: =COUNTIF(C1:C9,3) -> 1
B17: OTRO MEDIO | C17: =COUNTIF(C1:C9,4) -> 0
C19: =SUM(C14:C18) -> 9

Sheet PAGO
A1: COD | B1: PAGO
A2: 397
A3: 504 | B3: 45401
A4: 557 | B4: 45391
A5: 653 | B5: 45397
A6: 756 | B6: 45387
A7: 816 | B7: 45384
A8: 823 | B8: 45393
A9: 834 | B9: 45394
A10: 837
A11: 849 | B11: 45391
A12: 926
A13: 1021 | B13: 45397
A14: 1108 | B14: 45392
A15: 1159 | B15: 45411
A16: 1186 | B16: 45412
A17: 1413 | B17: 45391
A18: 1417 | B18: 45412
A19: 1449 | B19: 45412
A20: 1457 | B20: 45393
A21: 1462 | B21: 45406
A22: 1463 | B22: 45406
A23: 1469 | B23: 45404
A24: 1509 | B24: 45397
A25: 1526 | B25: 45397
A26: 1589
A27: 1597 | B27: 45409
A28: 1601 | B28: 45388
A29: 1639 | B29: 45397
A30: 1640 | B30: 45411
A31: 1647 | B31: 45411
A32: 1671 | B32: 45411
A33: 1673 | B33: 45395
A34: 1686 | B34: 45397
A35: 1699 | B35: 45394
A36: 1726 | B36: 45409
A37: 1762 | B37: 45392
A38: 1791 | B38: 45399
... A56: 2024 | B56: 45386
A57: 2039
...
