Workbook
Name _GoBack: AUTOHOGAR!#REF!
Name entrega: '[1]Sugerencia Rendiciones '!$BP$2:$BP$11
Name tipo: '[1]Sugerencia Rendiciones '!$D$3:$D$11

Sheet AUTOHOGAR
A1: 7 | B1: =IF(A1<>0,VLOOKUP(A1,COB!A1:B9,2),"COBRADOR INEXISTENTE") -> MEDIOS ELECTRONICOS | D1: AGOSTO | E1: 2026 | F1: TOTAL | I1: EL ARRASTE ES EL DINERO PENDIENTE O A FAVOR DEL CLIENTE | AI1: 15 C 1-6 | AS1: SI EL | AU1: SI EL CLIENTE
G2: A COBRAR | I2: PAGOS | N2: SAL. REAL | O2: SALDO | P2: SALDO /P ESTAD | Q2: FECHAS | Z2: SALDO P/ | AB2: PROBLEMAS | AC2: CORDOBA | AE2: NO PASO | AH2: TOTAL | AI2: 25 C 7-X | AS2: CLIEN PAGO | AU2: DEBE ALGO | AY2: CALCULO | AZ2: MOROSO | BA2: X ADEL | BD2: CALCULO | BE2: X ADEL | BF2: MOROSO
A3: COD | B3: CLIENTE | C3: TELEFONO | D3: LOCALIDAD | E3: SOLI | F3: CTA | G3: CUOTAS | H3: ARRASTRE | I3: PAGO | J3: PAGO X ADEL | K3: PAGO ANTES | L3: X OFICINA | M3: BCO O ELECT | N3: CON MORA | O3: SISTEMA | P3: PLANILLA SALIDA | Q3: PAGO | R3: PAGARA | S3: PAGO MES ANT | T3: BAJA | U3: MOTIVO | V3: OBSERVACIONES | W3: TERMOMETRO | X3: COB | Y3: COB XX | Z3: COMISION | AA3: PAGARA | AB3: CON VEND | AC3: CON VENTAS | AD3: CON PROP. EC | AE3: EL COB | AF3: OTROS | AG3: OBSERVACIONES | AH3: CLIENTES | AI3: paramet 1 | AJ3: paramet 2 | AK3: BAJAS 7-X | AL3: CLIENTES | AM3: MOTIVOS | AN3: $ | AO3: BAJAS 1-6 | AP3: CLIENTES | AQ3: MOTIVOS | AR3: $ | AS3: PAGADOS | AT3: CLIENTES | AU3: MORO O BAJA | AV3: N° CLIEN | AW3: MOROSOS 7 -X | AX3: CLIENTES | AY3: $ | BA3: $ | BB3: MOROSOS 1 -6 | BC3: CLIENTES | BD3: $ | BF3: $
A4: 816 | B4: GUEVARA ANTONIO NICOLAS | C4: 264-4837119 | D4: HUACO | E4: 9287 | F4: 93 | G4: 40000 | H4: 0 | M4: 40000 | N4: =IF(H4>0,G4+H4-I4-J4-K4-L4-M4,G4-I4-J4-K4-L4-M4) -> 0 | O4: =G4+H4-J4-I4-K4-L4-M4 -> 0 | P4: =IF(G4+H4<0,0,G4+H4) -> 40000 | Q4: 46237 | S4: 46205 | V4: MERCADO PAGO | X4: 7 | Y4: 7 | Z4: =IF(N4<0,0,N4) -> 0 | AH4: 1 | AI4: =IF(F4<=6,15,25) -> 25 | AJ4: =IF(O4<>0,25,15) -> 15 | AK4: =IF(AI4-T4=24,1,0) -> 0 | AL4: =IF(AH4-AK4=AH4,0,AH4) -> 0 | AM4: =IF(AK4<>0,U4,0) -> 0 | AN4: =IF(AK4=1,O4,0) -> 0 | AO4: =IF(AI4-T4=14,1,0) -> 0 | AP4: =IF(AH4-AO4=AH4,0,AH4) -> 0 | AQ4: =IF(AO4<>0,U4,0) -> 0 | AR4: =IF(AO4=1,O4,0) -> 0 | AS4: =IF(SUM(I4:M4)<>0,1,0) -> 1 | AT4: =AS4 -> 1 | AU4: =IF(O4>0,1,0) -> 0 | AV4: =IF(AK4+AO4+AU4=1,AU4,0) -> 0 | AW4: =IF(AI4-AV4=24,1,0) -> 0 | AX4: =IF(AH4-AW4=AH4,0,AH4) -> 0 | AY4: =IF(AW4=1,O4,0) -> 0 | AZ4: =IF(AY4-BA4<>0,AY4,0) -> 0 | BA4: =IF(AY4<0,AY4,0) -> 0 | BB4: =IF(AI4-AV4=14,1,0) -> 0 | BC4: =IF(AH4-BB4=AH4,0,AH4) -> 0 | BD4: =IF(BB4=1,O4,0) -> 0 | BE4: =IF(BD4<0,BD4,0) -> 0 | BF4: =IF(BD4-BE4<>0,BD4,0) -> 0
A5: 823 | B5: JOFRE ELIZABETH DEL VALLE | C5: 264-4122541 | D5: JACHAL | E5: 9375 | F5: 93 | G5: 30000 | H5: -3500 | M5: 30000 | N5: =IF(H5>0,G5+H5-I5-J5-K5-L5-M5,G5-I5-J5-K5-L5-M5) -> 0 | O5: =G5+H5-J5-I5-K5-L5-M5 -> -3500 | P5: =IF(G5+H5<0,0,G5+H5) -> 26500 | Q5: 46265 | R5: 46265 | S5: 46234 | V5: MERCADO PAGO | X5: 7 | Y5: 7 | Z5: =IF(N5<0,0,N5) -> 0 | AH5: 1 | AI5: =IF(F5<=6,15,25) -> 25 | AJ5: =IF(O5<>0,25,15) -> 25 | AK5: =IF(AI5-T5=24,1,0) -> 0 | AL5: =IF(AH5-AK5=AH5,0,AH5) -> 0 | AM5: =IF(AK5<>0,U5,0) -> 0 | AN5: =IF(AK5=1,O5,0) -> 0 | AO5: =IF(AI5-T5=14,1,0) -> 0 | AP5: =IF(AH5-AO5=AH5,0,AH5) -> 0 | AQ5: =IF(AO5<>0,U5,0) -> 0 | AR5: =IF(AO5=1,O5,0) -> 0 | AS5: =IF(SUM(I5:M5)<>0,1,0) -> 1 | AT5: =AS5 -> 1 | AU5: =IF(O5>0,1,0) -> 0 | AV5: =IF(AK5+AO5+AU5=1,AU5,0) -> 0 | AW5: =IF(AI5-AV5=24,1,0) -> 0 | AX5: =IF(AH5-AW5=AH5,0,AH5) -> 0 | AY5: =IF(AW5=1,O5,0) -> 0 | AZ5: =IF(AY5-BA5<>0,AY5,0) -> 0 | BA5: =IF(AY5<0,AY5,0) -> 0 | BB5: =IF(AI5-AV5=14,1,0) -> 0 | BC5: =IF(AH5-BB5=AH5,0,AH5) -> 0 | BD5: =IF(BB5=1,O5,0) -> 0 | BE5: =IF(BD5<0,BD5,0) -> 0 | BF5: =IF(BD5-BE5<>0,BD5,0) -> 0
A6: 834 | B6: BALMACEDA ESTER MARIA | C6: 2644442152 | D6: JACHAL | E6: 9034 | F6: 93 | G6: 60000 | H6: -4000 | M6: 60000 | N6: =IF(H6>0,G6+H6-I6-J6-K6-L6-M6,G6-I6-J6-K6-L6-M6) -> 0 | O6: =G6+H6-J6-I6-K6-L6-M6 -> -4000 | P6: =IF(G6+H6<0,0,G6+H6) -> 56000 | Q6: 46265 | R6: 46265 | S6: 46234 | V6: MERCADO PAGO | X6: 7 | Y6: 7 | Z6: =IF(N6<0,0,N6) -> 0 | AH6: 1 | AI6: =IF(F6<=6,15,25) -> 25 | AJ6: =IF(O6<>0,25,15) -> 25 | AK6: =IF(AI6-T6=24,1,0) -> 0 | AL6: =IF(AH6-AK6=AH6,0,AH6) -> 0 | AM6: =IF(AK6<>0,U6,0) -> 0 | AN6: =IF(AK6=1,O6,0) -> 0 | AO6: =IF(AI6-T6=14,1,0) -> 0 | AP6: =IF(AH6-AO6=AH6,0,AH6) -> 0 | AQ6: =IF(AO6<>0,U6,0) -> 0 | AR6: =IF(AO6=1,O6,0) -> 0 | AS6: =IF(SUM(I6:M6)<>0,1,0) -> 1 | AT6: =AS6 -> 1 | AU6: =IF(O6>0,1,0) -> 0 | AV6: =IF(AK6+AO6+AU6=1,AU6,0) -> 0 | AW6: =IF(AI6-AV6=24,1,0) -> 0 | AX6: =IF(AH6-AW6=AH6,0,AH6) -> 0 | AY6: =IF(AW6=1,O6,0) -> 0 | AZ6: =IF(AY6-BA6<>0,AY6,0) -> 0 | BA6: =IF(AY6<0,AY6,0) -> 0 | BB6: =IF(AI6-AV6=14,1,0) -> 0 | BC6: =IF(AH6-BB6=AH6,0,AH6) -> 0 | BD6: =IF(BB6=1,O6,0) -> 0 | BE6: =IF(BD6<0,BD6,0) -> 0 | BF6: =IF(BD6-BE6<>0,BD6,0) -> 0
A7: 1186 | B7: GARAY MARCELO | C7: 264-5269535 | D7: SAN JUAN | E7: 8984 | F7: 84 | G7: 80000 | H7: -24000 | M7: 80000 | N7: =IF(H7>0,G7+H7-I7-J7-K7-L7-M7,G7-I7-J7-K7-L7-M7) -> 0 | O7: =G7+H7-J7-I7-K7-L7-M7 -> -24000 | P7: =IF(G7+H7<0,0,G7+H7) -> 56000 | Q7: 46237 | R7: 46237 | S7: 46211 | V7: MERCADO PAGO | X7: 7 | Y7: 7 | Z7: =IF(N7<0,0,N7) -> 0 | AH7: 1 | AI7: =IF(F7<=6,15,25) -> 25 | AJ7: =IF(O7<>0,25,15) -> 25 | AK7: =IF(AI7-T7=24,1,0) -> 0 | AL7: =IF(AH7-AK7=AH7,0,AH7) -> 0 | AM7: =IF(AK7<>0,U7,0) -> 0 | AN7: =IF(AK7=1,O7,0) -> 0 | AO7: =IF(AI7-T7=14,1,0) -> 0 | AP7: =IF(AH7-AO7=AH7,0,AH7) -> 0 | AQ7: =IF(AO7<>0,U7,0) -> 0 | AR7: =IF(AO7=1,O7,0) -> 0 | AS7: =IF(SUM(I7:M7)<>0,1,0) -> 1 | AT7: =AS7 -> 1 | AU7: =IF(O7>0,1,0) -> 0 | AV7: =IF(AK7+AO7+AU7=1,AU7,0) -> 0 | AW7: =IF(AI7-AV7=24,1,0) -> 0 | AX7: =IF(AH7-AW7=AH7,0,AH7) -> 0 | AY7: =IF(AW7=1,O7,0) -> 0 | AZ7: =IF(AY7-BA7<>0,AY7,0) -> 0 | BA7: =IF(AY7<0,AY7,0) -> 0 | BB7: =IF(AI7-AV7=14,1,0) -> 0 | BC7: =IF(AH7-BB7=AH7,0,AH7) -> 0 | BD7: =IF(BB7=1,O7,0) -> 0 | BE7: =IF(BD7<0,BD7,0) -> 0 | BF7: =IF(BD7-BE7<>0,BD7,0) -> 0
A8: 1417 | B8: GARAY MARCELO ROBERTO | C8: 264-5269535 | D8: SAN JUAN | E8: 8539 | F8: 77 | G8: 80000 | H8: -6000 | M8: 80000 | N8: =IF(H8>0,G8+H8-I8-J8-K8-L8-M8,G8-I8-J8-K8-L8-M8) -> 0 | O8: =G8+H8-J8-I8-K8-L8-M8 -> -6000 | P8: =IF(G8+H8<0,0,G8+H8) -> 74000 | Q8: 46237 | R8: 46237 | S8: 46211 | V8: MERCADO PAGO | X8: 7 | Y8: 7 | Z8: =IF(N8<0,0,N8) -> 0 | AH8: 1 | AI8: =IF(F8<=6,15,25) -> 25 | AJ8: =IF(O8<>0,25,15) -> 25 | AK8: =IF(AI8-T8=24,1,0) -> 0 | AL8: =IF(AH8-AK8=AH8,0,AH8) -> 0 | AM8: =IF(AK8<>0,U8,0) -> 0 | AN8: =IF(AK8=1,O8,0) -> 0 | AO8: =IF(AI8-T8=14,1,0) -> 0 | AP8: =IF(AH8-AO8=AH8,0,AH8) -> 0 | AQ8: =IF(AO8<>0,U8,0) -> 0 | AR8: =IF(AO8=1,O8,0) -> 0 | AS8: =IF(SUM(I8:M8)<>0,1,0) -> 1 | AT8: =AS8 -> 1 | AU8: =IF(O8>0,1,0) -> 0 | AV8: =IF(AK8+AO8+AU8=1,AU8,0) -> 0 | AW8: =IF(AI8-AV8=24,1,0) -> 0 | AX8: =IF(AH8-AW8=AH8,0,AH8) -> 0 | AY8: =IF(AW8=1,O8,0) -> 0 | AZ8: =IF(AY8-BA8<>0,AY8,0) -> 0 | BA8: =IF(AY8<0,AY8,0) -> 0 | BB8: =IF(AI8-AV8=14,1,0) -> 0 | BC8: =IF(AH8-BB8=AH8,0,AH8) -> 0 | BD8: =IF(BB8=1,O8,0) -> 0 | BE8: =IF(BD8<0,BD8,0) -> 0 | BF8: =IF(BD8-BE8<>0,BD8,0) -> 0
A9: 1457 | B9: PASTEN EMILCE SABRINA | C9: 264-4739119 | D9: RIVADAVIA | E9: 8864 | F9: 76 | G9: 60000 | H9: -15000 | M9: 60000 | N9: =IF(H9>0,G9+H9-I9-J9-K9-L9-M9,G9-I9-J9-K9-L9-M9) -> 0 | O9: =G9+H9-J9-I9-K9-L9-M9 -> -15000 | P9: =IF(G9+H9<0,0,G9+H9) -> 45000 | Q9: 46265 | R9: 46265 | S9: 46234 | V9: MERCADO PAGO | X9: 7 | Y9: 7 | Z9: =IF(N9<0,0,N9) -> 0 | AH9: 1 | AI9: =IF(F9<=6,15,25) -> 25 | AJ9: =IF(O9<>0,25,15) -> 25 | AK9: =IF(AI9-T9=24,1,0) -> 0 | AL9: =IF(AH9-AK9=AH9,0,AH9) -> 0 | AM9: =IF(AK9<>0,U9,0) -> 0 | AN9: =IF(AK9=1,O9,0) -> 0 | AO9: =IF(AI9-T9=14,1,0) -> 0 | AP9: =IF(AH9-AO9=AH9,0,AH9) -> 0 | AQ9: =IF(AO9<>0,U9,0) -> 0 | AR9: =IF(AO9=1,O9,0) -> 0 | AS9: =IF(SUM(I9:M9)<>0,1,0) -> 1 | AT9: =AS9 -> 1 | AU9: =IF(O9>0,1,0) -> 0 | AV9: =IF(AK9+AO9+AU9=1,AU9,0) -> 0 | AW9: =IF(AI9-AV9=24,1,0) -> 0 | AX9: =IF(AH9-AW9=AH9,0,AH9) -> 0 | AY9: =IF(AW9=1,O9,0) -> 0 | AZ9: =IF(AY9-BA9<>0,AY9,0) -> 0 | BA9: =IF(AY9<0,AY9,0) -> 0 | BB9: =IF(AI9-AV9=14,1,0) -> 0 | BC9: =IF(AH9-BB9=AH9,0,AH9) -> 0 | BD9: =IF(BB9=1,O9,0) -> 0 | BE9: =IF(BD9<0,BD9,0) -> 0 | BF9: =IF(BD9-BE9<>0,BD9,0) -> 0
A10: 1597 | B10: ALMAZAN JUAN ARIEL | C10: 264-6245764 | D10: RAWSON | E10: 9625 | F10: 73 | G10: 60000 | H10: 0 | M10: 60000 | N10: =IF(H10>0,G10+H10-I10-J10-K10-L10-M10,G10-I10-J10-K10-L10-M10) -> 0 | O10: =G10+H10-J10-I10-K10-L10-M10 -> 0 | P10: =IF(G10+H10<0,0,G10+H10) -> 60000 | Q10: 46265 | R10: 46265 | S10: 46234 | V10: MERCADO PAGO | X10: 7 | Y10: 7 | Z10: =IF(N10<0,0,N10) -> 0 | AH10: 1 | AI10: =IF(F10<=6,15,25) -> 25 | AJ10: =IF(O10<>0,25,15) -> 15 | AK10: =IF(AI10-T10=24,1,0) -> 0 | AL10: =IF(AH10-AK10=AH10,0,AH10) -> 0 | AM10: =IF(AK10<>0,U10,0) -> 0 | AN10: =IF(AK10=1,O10,0) -> 0 | AO10: =IF(AI10-T10=14,1,0) -> 0 | AP10: =IF(AH10-AO10=AH10,0,AH10) -> 0 | AQ10: =IF(AO10<>0,U10,0) -> 0 | AR10: =IF(AO10=1,O10,0) -> 0 | AS10: =IF(SUM(I10:M10)<>0,1,0) -> 1 | AT10: =AS10 -> 1 | AU10: =IF(O10>0,1,0) -> 0 | AV10: =IF(AK10+AO10+AU10=1,AU10,0) -> 0 | AW10: =IF(AI10-AV10=24,1,0) -> 0 | AX10: =IF(AH10-AW10=AH10,0,AH10) -> 0 | AY10: =IF(AW10=1,O10,0) -> 0 | AZ10: =IF(AY10-BA10<>0,AY10,0) -> 0 | BA10: =IF(AY10<0,AY10,0) -> 0 | BB10: =IF(AI10-AV10=14,1,0) -> 0 | BC10: =IF(AH10-BB10=AH10,0,AH10) -> 0 | BD10: =IF(BB10=1,O10,0) -> 0 | BE10: =IF(BD10<0,BD10,0) -> 0 | BF10: =IF(BD10-BE10<>0,BD10,0) -> 0
A11: 1601 | B11: BUSTOS ELIZABETH NOEMI | C11: 264-5207638 | D11: SANTA LUCIA | E11: 9594 | F11: 73 | G11: 80000 | H11: 0 | M11: 80000 | N11: =IF(H11>0,G11+H11-I11-J11-K11-L11-M11,G11-I11-J11-K11-L11-M11) -> 0 | O11: =G11+H11-J11-I11-K11-L11-M11 -> 0 | P11: =IF(G11+H11<0,0,G11+H11) -> 80000 | Q11: 46238 | R11: 46238 | S11: 46209 | V11: MERCADO PAGO | X11: 7 | Y11: 7 | Z11: =IF(N11<0,0,N11) -> 0 | AH11: 1 | AI11: =IF(F11<=6,15,25) -> 25 | AJ11: =IF(O11<>0,25,15) -> 15 | AK11: =IF(AI11-T11=24,1,0) -> 0 | AL11: =IF(AH11-AK11=AH11,0,AH11) -> 0 | AM11: =IF(AK11<>0,U11,0) -> 0 | AN11: =IF(AK11=1,O11,0) -> 0 | AO11: =IF(AI11-T11=14,1,0) -> 0 | AP11: =IF(AH11-AO11=AH11,0,AH11) -> 0 | AQ11: =IF(AO11<>0,U11,0) -> 0 | AR11: =IF(AO11=1,O11,0) -> 0 | AS11: =IF(SUM(I11:M11)<>0,1,0) -> 1 | AT11: =AS11 -> 1 | AU11: =IF(O11>0,1,0) -> 0 | AV11: =IF(AK11+AO11+AU11=1,AU11,0) -> 0 | AW11: =IF(AI11-AV11=24,1,0) -> 0 | AX11: =IF(AH11-AW11=AH11,0,AH11) -> 0 | AY11: =IF(AW11=1,O11,0) -> 0 | AZ11: =IF(AY11-BA11<>0,AY11,0) -> 0 | BA11: =IF(AY11<0,AY11,0) -> 0 | BB11: =IF(AI11-AV11=14,1,0) -> 0 | BC11: =IF(AH11-BB11=AH11,0,AH11) -> 0 | BD11: =IF(BB11=1,O11,0) -> 0 | BE11: =IF(BD11<0,BD11,0) -> 0 | BF11: =IF(BD11-BE11<>0,BD11,0) -> 0
A12: 1671 | B12: TRIGO ESPEJO CARLOS JAVIER | C12: 2645414691 | D12: RAWSON | E12: 9740 | F12: 73 | G12: 30000 | H12: -32000 | M12: 30000 | N12: =IF(H12>0,G12+H12-I12-J12-K12-L12-M12,G12-I12-J12-K12-L12-M12) -> 0 | O12: =G12+H12-J12-I12-K12-L12-M12 -> -32000 | P12: =IF(G12+H12<0,0,G12+H12) -> 0 | Q12: 46265 | R12: 46265 | S12: 46234 | V12: MERCADO PAGO | X12: 7 | Y12: 7 | Z12: =IF(N12<0,0,N12) -> 0 | AH12: 1 | AI12: =IF(F12<=6,15,25) -> 25 | AJ12: =IF(O12<>0,25,15) -> 25 | AK12: =IF(AI12-T12=24,1,0) -> 0 | AL12: =IF(AH12-AK12=AH12,0,AH12) -> 0 | AM12: =IF(AK12<>0,U12,0) -> 0 | AN12: =IF(AK12=1,O12,0) -> 0 | AO12: =IF(AI12-T12=14,1,0) -> 0 | AP12: =IF(AH12-AO12=AH12,0,AH12) -> 0 | AQ12: =IF(AO12<>0,U12,0) -> 0 | AR12: =IF(AO12=1,O12,0) -> 0 | AS12: =IF(SUM(I12:M12)<>0,1,0) -> 1 | AT12: =AS12 -> 1 | AU12: =IF(O12>0,1,0) -> 0 | AV12: =IF(AK12+AO12+AU12=1,AU12,0) -> 0 | AW12: =IF(AI12-AV12=24,1,0) -> 0 | AX12: =IF(AH12-AW12=AH12,0,AH12) -> 0 | AY12: =IF(AW12=1,O12,0) -> 0 | AZ12: =IF(AY12-BA12<>0,AY12,0) -> 0 | BA12: =IF(AY12<0,AY12,0) -> 0 | BB12: =IF(AI12-AV12=14,1,0) -> 0 | BC12: =IF(AH12-BB12=AH12,0,AH12) -> 0 | BD12: =IF(BB12=1,O12,0) -> 0 | BE12: =IF(BD12<0,BD12,0) -> 0 | BF12: =IF(BD12-BE12<>0,BD12,0) -> 0
A13: 1791 | B13: MUÑOZ ALICIA ADRIANA | C13: 264-4700323 | D13: CHIMBAS | E13: 9908 | F13: 71 | G13: 60000 | H13: -15000 | M13: 60000 | N13: =IF(H13>0,G13+H13-I13-J13-K13-L13-M13,G13-I13-J13-K13-L13-M13) -> 0 | O13: =G13+H13-J13-I13-K13-L13-M13 -> -15000 | P13: =IF(G13+H13<0,0,G13+H13) -> 45000 | Q13: 46259 | R13: 46252 | S13: 46223 | V13: EFECTIVO OFICINA | X13: 7 | Y13: 7 | Z13: =IF(N13<0,0,N13) -> 0 | AH13: 1 | AI13: =IF(F13<=6,15,25) -> 25 | AJ13: =IF(O13<>0,25,15) -> 25 | AK13: =IF(AI13-T13=24,1,0) -> 0 | AL13: =IF(AH13-AK13=AH13,0,AH13) -> 0 | AM13: =IF(AK13<>0,U13,0) -> 0 | AN13: =IF(AK13=1,O13,0) -> 0 | AO13: =IF(AI13-T13=14,1,0) -> 0 | AP13: =IF(AH13-AO13=AH13,0,AH13) -> 0 | AQ13: =IF(AO13<>0,U13,0) -> 0 | AR13: =IF(AO13=1,O13,0) -> 0 | AS13: =IF(SUM(I13:M13)<>0,1,0) -> 1 | AT13: =AS13 -> 1 | AU13: =IF(O13>0,1,0) -> 0 | AV13: =IF(AK13+AO13+AU13=1,AU13,0) -> 0 | AW13: =IF(AI13-AV13=24,1,0) -> 0 | AX13: =IF(AH13-AW13=AH13,0,AH13) -> 0 | AY13: =IF(AW13=1,O13,0) -> 0 | AZ13: =IF(AY13-BA13<>0,AY13,0) -> 0 | BA13: =IF(AY13<0,AY13,0) -> 0 | BB13: =IF(AI13-AV13=14,1,0) -> 0 | BC13: =IF(AH13-BB13=AH13,0,AH13) -> 0 | BD13: =IF(BB13=1,O13,0) -> 0 | BE13: =IF(BD13<0,BD13,0) -> 0 | BF13: =IF(BD13-BE13<>0,BD13,0) -> 0
A14: 1829 | B14: MANRIQUE BRIZUELA BARBARA ELIZABETH | C14: 2644112914 | D14: JACHAL | E14: 9936 | F14: 70 | G14: 300000 | H14: -5000 | M14: 300000 | N14: =IF(H14>0,G14+H14-I14-J14-K14-L14-M14,G14-I14-J14-K14-L14-M14) -> 0 | O14: =G14+H14-J14-I14-K14-L14-M14 -> -5000 | P14: =IF(G14+H14<0,0,G14+H14) -> 295000 | Q14: 46255 | R14: 46255 | S14: 46234 | V14: MERCADO PAGO | X14: 7 | Y14: 7 | Z14: =IF(N14<0,0,N14) -> 0 | AH14: 1 | AI14: =IF(F14<=6,15,25) -> 25 | AJ14: =IF(O14<>0,25,15) -> 25 | AK14: =IF(AI14-T14=24,1,0) -> 0 | AL14: =IF(AH14-AK14=AH14,0,AH14) -> 0 | AM14: =IF(AK14<>0,U14,0) -> 0 | AN14: =IF(AK14=1,O14,0) -> 0 | AO14: =IF(AI14-T14=14,1,0) -> 0 | AP14: =IF(AH14-AO14=AH14,0,AH14) -> 0 | AQ14: =IF(AO14<>0,U14,0) -> 0 | AR14: =IF(AO14=1,O14,0) -> 0 | AS14: =IF(SUM(I14:M14)<>0,1,0) -> 1 | AT14: =AS14 -> 1 | AU14: =IF(O14>0,1,0) -> 0 | AV14: =IF(AK14+AO14+AU14=1,AU14,0) -> 0 | AW14: =IF(AI14-AV14=24,1,0) -> 0 | AX14: =IF(AH14-AW14=AH14,0,AH14) -> 0 | AY14: =IF(AW14=1,O14,0) -> 0 | AZ14: =IF(AY14-BA14<>0,AY14,0) -> 0 | BA14: =IF(AY14<0,AY14,0) -> 0 | BB14: =IF(AI14-AV14=14,1,0) -> 0 | BC14: =IF(AH14-BB14=AH14,0,AH14) -> 0 | BD14: =IF(BB14=1,O14,0) -> 0 | BE14: =IF(BD14<0,BD14,0) -> 0 | BF14: =IF(BD14-BE14<>0,BD14,0) -> 0
A15: 1870 | B15: OCHOA ERICA DEBORA | C15: 264-5178841 | D15: SAN JUAN | E15: 9889 | F15: 69 | G15: 40000 | H15: 0 | I15: 40000 | N15: =IF(H15>0,G15+H15-I15-J15-K15-L15-M15,G15-I15-J15-K15-L15-M15) -> 0 | O15: =G15+H15-J15-I15-K15-L15-M15 -> 0 | P15: =IF(G15+H15<0,0,G15+H15) -> 40000 | Q15: 46245 | R15: 46245 | S15: 46225 | V15: EFECTIVO | X15: 7 | Y15: 7 | Z15: =IF(N15<0,0,N15) -> 0 | AH15: 1 | AI15: =IF(F15<=6,15,25) -> 25 | AJ15: =IF(O15<>0,25,15) -> 15 | AK15: =IF(AI15-T15=24,1,0) -> 0 | AL15: =IF(AH15-AK15=AH15,0,AH15) -> 0 | AM15: =IF(AK15<>0,U15,0) -> 0 | AN15: =IF(AK15=1,O15,0) -> 0 | AO15: =IF(AI15-T15=14,1,0) -> 0 | AP15: =IF(AH15-AO15=AH15,0,AH15) -> 0 | AQ15: =IF(AO15<>0,U15,0) -> 0 | AR15: =IF(AO15=1,O15,0) -> 0 | AS15: =IF(SUM(I15:M15)<>0,1,0) -> 1 | AT15: =AS15 -> 1 | AU15: =IF(O15>0,1,0) -> 0 | AV15: =IF(AK15+AO15+AU15=1,AU15,0) -> 0 | AW15: =IF(AI15-AV15=24,1,0) -> 0 | AX15: =IF(AH15-AW15=AH15,0,AH15) -> 0 | AY15: =IF(AW15=1,O15,0) -> 0 | AZ15: =IF(AY15-BA15<>0,AY15,0) -> 0 | BA15: =IF(AY15<0,AY15,0) -> 0 | BB15: =IF(AI15-AV15=14,1,0) -> 0 | BC15: =IF(AH15-BB15=AH15,0,AH15) -> 0 | BD15: =IF(BB15=1,O15,0) -> 0 | BE15: =IF(BD15<0,BD15,0) -> 0 | BF15: =IF(BD15-BE15<>0,BD15,0) -> 0
A16: 1871 | B16: FERNANDEZ GORIA GABRIELA CELESTE | C16: 264-5676031 | D16: RIVADAVIA | E16: 9891 | F16: 69 | G16: 35000 | H16: 0 | M16: 35000 | N16: =IF(H16>0,G16+H16-I16-J16-K16-L16-M16,G16-I16-J16-K16-L16-M16) -> 0 | O16: =G16+H16-J16-I16-K16-L16-M16 -> 0 | P16: =IF(G16+H16<0,0,G16+H16) -> 35000 | Q16: 46265 | R16: 46265 | S16: 46234 | V16: MERCADO PAGO | X16: 7 | Y16: 7 | Z16: =IF(N16<0,0,N16) -> 0 | AH16: 1 | AI16: =IF(F16<=6,15,25) -> 25 | AJ16: =IF(O16<>0,25,15) -> 15 | AK16: =IF(AI16-T16=24,1,0) -> 0 | AL16: =IF(AH16-AK16=AH16,0,AH16) -> 0 | AM16: =IF(AK16<>0,U16,0) -> 0 | AN16: =IF(AK16=1,O16,0) -> 0 | AO16: =IF(AI16-T16=14,1,0) -> 0 | AP16: =IF(AH16-AO16=AH16,0,AH16) -> 0 | AQ16: =IF(AO16<>0,U16,0) -> 0 | AR16: =IF(AO16=1,O16,0) -> 0 | AS16: =IF(SUM(I16:M16)<>0,1,0) -> 1 | AT16: =AS16 -> 1 | AU16: =IF(O16>0,1,0) -> 0 | AV16: =IF(AK16+AO16+AU16=1,AU16,0) -> 0 | AW16: =IF(AI16-AV16=24,1,0) -> 0 | AX16: =IF(AH16-AW16=AH16,0,AH16) -> 0 | AY16: =IF(AW16=1,O16,0) -> 0 | AZ16: =IF(AY16-BA16<>0,AY16,0) -> 0 | BA16: =IF(AY16<0,AY16,0) -> 0 | BB16: =IF(AI16-AV16=14,1,0) -> 0 | BC16: =IF(AH16-BB16=AH16,0,AH16) -> 0 | BD16: =IF(BB16=1,O16,0) -> 0 | BE16: =IF(BD16<0,BD16,0) -> 0 | BF16: =IF(BD16-BE16<>0,BD16,0) -> 0
A17: 1900 | B17: CERDA FABIAN ALEJANDRO | C17: 264-6621777 | D17: CHIMBAS | E17: 10012 | F17: 69 | G17: 60000 | H17: -60000 | M17: 60000 | N17: =IF(H17>0,G17+H17-I17-J17-K17-L17-M17,G17-I17-J17-K17-L17-M17) -> 0 | O17: =G17+H17-J17-I17-K17-L17-M17 -> -60000 | P17: =IF(G17+H17<0,0,G17+H17) -> 0 | Q17: 46265 | R17: 46265 | S17: 46234 | V17: MERCADO PAGO | X17: 7 | Y17: 7 | Z17: =IF(N17<0,0,N17) -> 0 | AH17: 1 | AI17: =IF(F17<=6,15,25) -> 25 | AJ17: =IF(O17<>0,25,15) -> 25 | AK17: =IF(AI17-T17=24,1,0) -> 0 | AL17: =IF(AH17-AK17=AH17,0,AH17) -> 0 | AM17: =IF(AK17<>0,U17,0) -> 0 | AN17: =IF(AK17=1,O17,0) -> 0 | AO17: =IF(AI17-T17=14,1,0) -> 0 | AP17: =IF(AH17-AO17=AH17,0,AH17) -> 0 | AQ17: =IF(AO17<>0,U17,0) -> 0 | AR17: =IF(AO17=1,O17,0) -> 0 | AS17: =IF(SUM(I17:M17)<>0,1,0) -> 1 | AT17: =AS17 -> 1 | AU17: =IF(O17>0,1,0) -> 0 | AV17: =IF(AK17+AO17+AU17=1,AU17,0) -> 0 | AW17: =IF(AI17-AV17=24,1,0) -> 0 | AX17: =IF(AH17-AW17=AH17,0,AH17) -> 0 | AY17: =IF(AW17=1,O17,0) -> 0 | AZ17: =IF(AY17-BA17<>0,AY17,0) -> 0 | BA17: =IF(AY17<0,AY17,0) -> 0 | BB17: =IF(AI17-AV17=14,1,0) -> 0 | BC17: =IF(AH17-BB17=AH17,0,AH17) -> 0 | BD17: =IF(BB17=1,O17,0) -> 0 | BE17: =IF(BD17<0,BD17,0) -> 0 | BF17: =IF(BD17-BE17<>0,BD17,0) -> 0
A18: 1954 | B18: GUTIERREZ ATENCIO ELDA VANESA | C18: 264-4580614 | D18: ZONDA | E18: 10045 | F18: 67 | G18: 50000 | H18: -30000 | M18: 50000 | N18: =IF(H18>0,G18+H18-I18-J18-K18-L18-M18,G18-I18-J18-K18-L18-M18) -> 0 | O18: =G18+H18-J18-I18-K18-L18-M18 -> -30000 | P18: =IF(G18+H18<0,0,G18+H18) -> 20000 | Q18: 46237 | R18: 46237 | S18: 46204 | V18: MERCADO PAGO | X18: 7 | Y18: 7 | Z18: =IF(N18<0,0,N18) -> 0 | AH18: 1 | AI18: =IF(F18<=6,15,25) -> 25 | AJ18: =IF(O18<>0,25,15) -> 25 | AK18: =IF(AI18-T18=24,1,0) -> 0 | AL18: =IF(AH18-AK18=AH18,0,AH18) -> 0 | AM18: =IF(AK18<>0,U18,0) -> 0 | AN18: =IF(AK18=1,O18,0) -> 0 | AO18: =IF(AI18-T18=14,1,0) -> 0 | AP18: =IF(AH18-AO18=AH18,0,AH18) -> 0 | AQ18: =IF(AO18<>0,U18,0) -> 0 | AR18: =IF(AO18=1,O18,0) -> 0 | AS18: =IF(SUM(I18:M18)<>0,1,0) -> 1 | AT18: =AS18 -> 1 | AU18: =IF(O18>0,1,0) -> 0 | AV18: =IF(AK18+AO18+AU18=1,AU18,0) -> 0 | AW18: =IF(AI18-AV18=24,1,0) -> 0 | AX18: =IF(AH18-AW18=AH18,0,AH18) -> 0 | AY18: =IF(AW18=1,O18,0) -> 0 | AZ18: =IF(AY18-BA18<>0,AY18,0) -> 0 | BA18: =IF(AY18<0,AY18,0) -> 0 | BB18: =IF(AI18-AV18=14,1,0) -> 0 | BC18: =IF(AH18-BB18=AH18,0,AH18) -> 0 | BD18: =IF(BB18=1,O18,0) -> 0 | BE18: =IF(BD18<0,BD18,0) -> 0 | BF18: =IF(BD18-BE18<>0,BD18,0) -> 0
A19: 1999 | B19: PEREZ JOSE ISMAEL | C19: 264-5122570 | D19: SAN JUAN | E19: 10192 | F19: 66 | G19: 60000 | H19: -75000 | M19: 120000 | N19: =IF(H19>0,G19+H19-I19-J19-K19-L19-M19,G19-I19-J19-K19-L19-M19) -> -60000 | O19: =G19+H19-J19-I19-K19-L19-M19 -> -135000 | P19: =IF(G19+H19<0,0,G19+H19) -> 0 | Q19: 46265 | R19: 46244 | S19: 46213 | V19: MERCADO PAGO | W19: PAGO AGOSTO Y SEPTIEMBRE | X19: 7 | Y19: 7 | Z19: =IF(N19<0,0,N19) -> 0 | AH19: 1 | AI19: =IF(F19<=6,15,25) -> 25 | AJ19: =IF(O19<>0,25,15) -> 25 | AK19: =IF(AI19-T19=24,1,0) -> 0 | AL19: =IF(AH19-AK19=AH19,0,AH19) -> 0 | AM19: =IF(AK19<>0,U19,0) -> 0 | AN19: =IF(AK19=1,O19,0) -> 0 | AO19: =IF(AI19-T19=14,1,0) -> 0 | AP19: =IF(AH19-AO19=AH19,0,AH19) -> 0 | AQ19: =IF(AO19<>0,U19,0) -> 0 | AR19: =IF(AO19=1,O19,0) -> 0 | AS19: =IF(SUM(I19:M19)<>0,1,0) -> 1 | AT19: =AS19 -> 1 | AU19: =IF(O19>0,1,0) -> 0 | AV19: =IF(AK19+AO19+AU19=1,AU19,0) -> 0 | AW19: =IF(AI19-AV19=24,1,0) -> 0 | AX19: =IF(AH19-AW19=AH19,0,AH19) -> 0 | AY19: =IF(AW19=1,O19,0) -> 0 | AZ19: =IF(AY19-BA19<>0,AY19,0) -> 0 | BA19: =IF(AY19<0,AY19,0) -> 0 | BB19: =IF(AI19-AV19=14,1,0) -> 0 | BC19: =IF(AH19-BB19=AH19,0,AH19) -> 0 | BD19: =IF(BB19=1,O19,0) -> 0 | BE19: =IF(BD19<0,BD19,0) -> 0 | BF19: =IF(BD19-BE19<>0,BD19,0) -> 0
A20: 2010 | B20: PEREYRA NUVIA CELESTE | C20: 264-4829505 | D20: SANTA LUCIA | E20: 10206 | F20: 66 | G20: 30000 | H20: -28000 | M20: 30000 | N20: =IF(H20>0,G20+H20-I20-J20-K20-L20-M20,G20-I20-J20-K20-L20-M20) -> 0 | O20: =G20+H20-J20-I20-K20-L20-M20 -> -28000 | P20: =IF(G20+H20<0,0,G20+H20) -> 2000 | Q20: 46265 | R20: 46265 | S20: 46234 | V20: MERCADO PAGO | X20: 7 | Y20: 7 | Z20: =IF(N20<0,0,N20) -> 0 | AH20: 1 | AI20: =IF(F20<=6,15,25) -> 25 | AJ20: =IF(O20<>0,25,15) -> 25 | AK20: =IF(AI20-T20=24,1,0) -> 0 | AL20: =IF(AH20-AK20=AH20,0,AH20) -> 0 | AM20: =IF(AK20<>0,U20,0) -> 0 | AN20: =IF(AK20=1,O20,0) -> 0 | AO20: =IF(AI20-T20=14,1,0) -> 0 | AP20: =IF(AH20-AO20=AH20,0,AH20) -> 0 | AQ20: =IF(AO20<>0,U20,0) -> 0 | AR20: =IF(AO20=1,O20,0) -> 0 | AS20: =IF(SUM(I20:M20)<>0,1,0) -> 1 | AT20: =AS20 -> 1 | AU20: =IF(O20>0,1,0) -> 0 | AV20: =IF(AK20+AO20+AU20=1,AU20,0) -> 0 | AW20: =IF(AI20-AV20=24,1,0) -> 0 | AX20: =IF(AH20-AW20=AH20,0,AH20) -> 0 | AY20: =IF(AW20=1,O20,0) -> 0 | AZ20: =IF(AY20-BA20<>0,AY20,0) -> 0 | BA20: =IF(AY20<0,AY20,0) -> 0 | BB20: =IF(AI20-AV20=14,1,0) -> 0 | BC20: =IF(AH20-BB20=AH20,0,AH20) -> 0 | BD20: =IF(BB20=1,O20,0) -> 0 | BE20: =IF(BD20<0,BD20,0) -> 0 | BF20: =IF(BD20-BE20<>0,BD20,0) -> 0
A21: 2015 | B21: ELIZONDO MARIO SANTIAGO | C21: 264-5061888 | D21: ALBARDON | E21: 10189 | F21: 66 | G21: 70000 | H21: -118000 | N21: =IF(H21>0,G21+H21-I21-J21-K21-L21-M21,G21-I21-J21-K21-L21-M21) -> 70000 | O21: =G21+H21-J21-I21-K21-L21-M21 -> -48000 | P21: =IF(G21+H21<0,0,G21+H21) -> 0 | S21: 70000 | T21: 1 | U21: 1 | V21: BAJA Y DEVOLUCION | X21: 7 | Y21: 7 | Z21: =IF(N21<0,0,N21) -> 70000 | AH21: 1 | AI21: =IF(F21<=6,15,25) -> 25 | AJ21: =IF(O21<>0,25,15) -> 25 | AK21: =IF(AI21-T21=24,1,0) -> 1 | AL21: =IF(AH21-AK21=AH21,0,AH21) -> 1 | AM21: =IF(AK21<>0,U21,0) -> 1 | AN21: =IF(AK21=1,O21,0) -> -48000 | AO21: =IF(AI21-T21=14,1,0) -> 0 | AP21: =IF(AH21-AO21=AH21,0,AH21) -> 0 | AQ21: =IF(AO21<>0,U21,0) -> 0 | AR21: =IF(AO21=1,O21,0) -> 0 | AS21: =IF(SUM(I21:M21)<>0,1,0) -> 0 | AT21: =AS21 -> 0 | AU21: =IF(O21>0,1,0) -> 0 | AV21: =IF(AK21+AO21+AU21=1,AU21,0) -> 0 | AW21: =IF(AI21-AV21=24,1,0) -> 0 | AX21: =IF(AH21-AW21=AH21,0,AH21) -> 0 | AY21: =IF(AW21=1,O21,0) -> 0 | AZ21: =IF(AY21-BA21<>0,AY21,0) -> 0 | BA21: =IF(AY21<0,AY21,0) -> 0 | BB21: =IF(AI21-AV21=14,1,0) -> 0 | BC21: =IF(AH21-BB21=AH21,0,AH21) -> 0 | BD21: =IF(BB21=1,O21,0) -> 0 | BE21: =IF(BD21<0,BD21,0) -> 0 | BF21: =IF(BD21-BE21<>0,BD21,0) -> 0
A22: 2024 | B22: BUENO VALERIA VANESA | C22: 264-5435239 | D22: RAWSON | E22: 10095 | F22: 66 | G22: 30000 | H22: -24000 | M22: 30000 | N22: =IF(H22>0,G22+H22-I22-J22-K22-L22-M22,G22-I22-J22-K22-L22-M22) -> 0 | O22: =G22+H22-J22-I22-K22-L22-M22 -> -24000 | P22: =IF(G22+H22<0,0,G22+H22) -> 6000 | Q22: 46239 | R22: 46240 | S22: 46209 | V22: MERCADO PAGO | X22: 7 | Y22: 7 | Z22: =IF(N22<0,0,N22) -> 0 | AH22: 1 | AI22: =IF(F22<=6,15,25) -> 25 | AJ22: =IF(O22<>0,25,15) -> 25 | AK22: =IF(AI22-T22=24,1,0) -> 0 | AL22: =IF(AH22-AK22=AH22,0,AH22) -> 0 | AM22: =IF(AK22<>0,U22,0) -> 0 | AN22: =IF(AK22=1,O22,0) -> 0 | AO22: =IF(AI22-T22=14,1,0) -> 0 | AP22: =IF(AH22-AO22=AH22,0,AH22) -> 0 | AQ22: =IF(AO22<>0,U22,0) -> 0 | AR22: =IF(AO22=1,O22,0) -> 0 | AS22: =IF(SUM(I22:M22)<>0,1,0) -> 1 | AT22: =AS22 -> 1 | AU22: =IF(O22>0,1,0) -> 0 | AV22: =IF(AK22+AO22+AU22=1,AU22,0) -> 0 | AW22: =IF(AI22-AV22=24,1,0) -> 0 | AX22: =IF(AH22-AW22=AH22,0,AH22) -> 0 | AY22: =IF(AW22=1,O22,0) -> 0 | AZ22: =IF(AY22-BA22<>0,AY22,0) -> 0 | BA22: =IF(AY22<0,AY22,0) -> 0 | BB22: =IF(AI22-AV22=14,1,0) -> 0 | BC22: =IF(AH22-BB22=AH22,0,AH22) -> 0 | BD22: =IF(BB22=1,O22,0) -> 0 | BE22: =IF(BD22<0,BD22,0) -> 0 | BF22: =IF(BD22-BE22<>0,BD22,0) -> 0
A23: 2095 | B23: PAREDES HUGO ARIEL | C23: 264-7409479 | D23: RODEO | E23: 10288 | F23: 64 | G23: 65000 | H23: 0 | M23: 65000 | N23: =IF(H23>0,G23+H23-I23-J23-K23-L23-M23,G23-I23-J23-K23-L23-M23) -> 0 | O23: =G23+H23-J23-I23-K23-L23-M23 -> 0 | P23: =IF(G23+H23<0,0,G23+H23) -> 65000 | Q23: 46241 | R23: 46241 | S23: 46211 | V23: MERCADO PAGO | X23: 7 | Y23: 7 | Z23: =IF(N23<0,0,N23) -> 0 | AH23: 1 | AI23: =IF(F23<=6,15,25) -> 25 | AJ23: =IF(O23<>0,25,15) -> 15 | AK23: =IF(AI23-T23=24,1,0) -> 0 | AL23: =IF(AH23-AK23=AH23,0,AH23) -> 0 | AM23: =IF(AK23<>0,U23,0) -> 0 | AN23: =IF(AK23=1,O23,0) -> 0 | AO23: =IF(AI23-T23=14,1,0) -> 0 | AP23: =IF(AH23-AO23=AH23,0,AH23) -> 0 | AQ23: =IF(AO23<>0,U23,0) -> 0 | AR23: =IF(AO23=1,O23,0) -> 0 | AS23: =IF(SUM(I23:M23)<>0,1,0) -> 1 | AT23: =AS23 -> 1 | AU23: =IF(O23>0,1,0) -> 0 | AV23: =IF(AK23+AO23+AU23=1,AU23,0) -> 0 | AW23: =IF(AI23-AV23=24,1,0) -> 0 | AX23: =IF(AH23-AW23=AH23,0,AH23) -> 0 | AY23: =IF(AW23=1,O23,0) -> 0 | AZ23: =IF(AY23-BA23<>0,AY23,0) -> 0 | BA23: =IF(AY23<0,AY23,0) -> 0 | BB23: =IF(AI23-AV23=14,1,0) -> 0 | BC23: =IF(AH23-BB23=AH23,0,AH23) -> 0 | BD23: =IF(BB23=1,O23,0) -> 0 | BE23: =IF(BD23<0,BD23,0) -> 0 | BF23: =IF(BD23-BE23<>0,BD23,0) -> 0
A24: 2119 | B24: RIVEROS HUGO GUSTAVO | C24: 264-4816549 | D24: CHIMBAS | E24: 10430 | F24: 63 | G24: 30000 | H24: 0 | M24: 30000 | N24: =IF(H24>0,G24+H24-I24-J24-K24-L24-M24,G24-I24-J24-K24-L24-M24) -> 0 | O24: =G24+H24-J24-I24-K24-L24-M24 -> 0 | P24: =IF(G24+H24<0,0,G24+H24) -> 30000 | Q24: 46239 | R24: 46239 | S24: 46176 | V24: MERCADO PAGO | X24: 7 | Y24: 7 | Z24: =IF(N24<0,0,N24) -> 0 | AH24: 1 | AI24: =IF(F24<=6,15,25) -> 25 | AJ24: =IF(O24<>0,25,15) -> 15 | AK24: =IF(AI24-T24=24,1,0) -> 0 | AL24: =IF(AH24-AK24=AH24,0,AH24) -> 0 | AM24: =IF(AK24<>0,U24,0) -> 0 | AN24: =IF(AK24=1,O24,0) -> 0 | AO24: =IF(AI24-T24=14,1,0) -> 0 | AP24: =IF(AH24-AO24=AH24,0,AH24) -> 0 | AQ24: =IF(AO24<>0,U24,0) -> 0 | AR24: =IF(AO24=1,O24,0) -> 0 | AS24: =IF(SUM(I24:M24)<>0,1,0) -> 1 | AT24: =AS24 -> 1 | AU24: =IF(O24>0,1,0) -> 0 | AV24: =IF(AK24+AO24+AU24=1,AU24,0) -> 0 | AW24: =IF(AI24-AV24=24,1,0) -> 0 | AX24: =IF(AH24-AW24=AH24,0,AH24) -> 0 | AY24: =IF(AW24=1,O24,0) -> 0 | AZ24: =IF(AY24-BA24<>0,AY24,0) -> 0 | BA24: =IF(AY24<0,AY24,0) -> 0 | BB24: =IF(AI24-AV24=14,1,0) -> 0 | BC24: =IF(AH24-BB24=AH24,0,AH24) -> 0 | BD24: =IF(BB24=1,O24,0) -> 0 | BE24: =IF(BD24<0,BD24,0) -> 0 | BF24: =IF(BD24-BE24<>0,BD24,0) -> 0
A25: 2120 | B25: CALDERON ROSANA ANALIA | C25: 264-5315461 | D25: CHIMBAS | E25: 10281 | F25: 63 | G25: 500000 | H25: -80000 | M25: 500000 | N25: =IF(H25>0,G25+H25-I25-J25-K25-L25-M25,G25-I25-J25-K25-L25-M25) -> 0 | O25: =G25+H25-J25-I25-K25-L25-M25 -> -80000 | P25: =IF(G25+H25<0,0,G25+H25) -> 420000 | Q25: 46209 | R25: 46208 | S25: 46176 | V25: MERCADO PAGO | X25: 7 | Y25: 7 | Z25: =IF(N25<0,0,N25) -> 0 | AH25: 1 | AI25: =IF(F25<=6,15,25) -> 25 | AJ25: =IF(O25<>0,25,15) -> 25 | AK25: =IF(AI25-T25=24,1,0) -> 0 | AL25: =IF(AH25-AK25=AH25,0,AH25) -> 0 | AM25: =IF(AK25<>0,U25,0) -> 0 | AN25: =IF(AK25=1,O25,0) -> 0 | AO25: =IF(AI25-T25=14,1,0) -> 0 | AP25: =IF(AH25-AO25=AH25,0,AH25) -> 0 | AQ25: =IF(AO25<>0,U25,0) -> 0 | AR25: =IF(AO25=1,O25,0) -> 0 | AS25: =IF(SUM(I25:M25)<>0,1,0) -> 1 | AT25: =AS25 -> 1 | AU25: =IF(O25>0,1,0) -> 0 | AV25: =IF(AK25+AO25+AU25=1,AU25,0) -> 0 | AW25: =IF(AI25-AV25=24,1,0) -> 0 | AX25: =IF(AH25-AW25=AH25,0,AH25) -> 0 | AY25: =IF(AW25=1,O25,0) -> 0 | AZ25: =IF(AY25-BA25<>0,AY25,0) -> 0 | BA25: =IF(AY25<0,AY25,0) -> 0 | BB25: =IF(AI25-AV25=14,1,0) -> 0 | BC25: =IF(AH25-BB25=AH25,0,AH25) -> 0 | BD25: =IF(BB25=1,O25,0) -> 0 | BE25: =IF(BD25<0,BD25,0) -> 0 | BF25: =IF(BD25-BE25<>0,BD25,0) -> 0
A26: 2207 | B26: ORELLANO VERA YESICA BEATRIZ | C26: 2644656518 | D26: RAWSON | E26: 10449 | F26: 61 | G26: 60000 | H26: 0 | M26: 60000 | N26: =IF(H26>0,G26+H26-I26-J26-K26-L26-M26,G26-I26-J26-K26-L26-M26) -> 0 | O26: =G26+H26-J26-I26-K26-L26-M26 -> 0 | P26: =IF(G26+H26<0,0,G26+H26) -> 60000 | Q26: 46245 | R26: 46245 | S26: 46209 | V26: GALICIA | X26: 7 | Y26: 7 | Z26: =IF(N26<0,0,N26) -> 0 | AH26: 1 | AI26: =IF(F26<=6,15,25) -> 25 | AJ26: =IF(O26<>0,25,15) -> 15 | AK26: =IF(AI26-T26=24,1,0) -> 0 | AL26: =IF(AH26-AK26=AH26,0,AH26) -> 0 | AM26: =IF(AK26<>0,U26,0) -> 0 | AN26: =IF(AK26=1,O26,0) -> 0 | AO26: =IF(AI26-T26=14,1,0) -> 0 | AP26: =IF(AH26-AO26=AH26,0,AH26) -> 0 | AQ26: =IF(AO26<>0,U26,0) -> 0 | AR26: =IF(AO26=1,O26,0) -> 0 | AS26: =IF(SUM(I26:M26)<>0,1,0) -> 1 | AT26: =AS26 -> 1 | AU26: =IF(O26>0,1,0) -> 0 | AV26: =IF(AK26+AO26+AU26=1,AU26,0) -> 0 | AW26: =IF(AI26-AV26=24,1,0) -> 0 | AX26: =IF(AH26-AW26=AH26,0,AH26) -> 0 | AY26: =IF(AW26=1,O26,0) -> 0 | AZ26: =IF(AY26-BA26<>0,AY26,0) -> 0 | BA26: =IF(AY26<0,AY26,0) -> 0 | BB26: =IF(AI26-AV26=14,1,0) -> 0 | BC26: =IF(AH26-BB26=AH26,0,AH26) -> 0 | BD26: =IF(BB26=1,O26,0) -> 0 | BE26: =IF(BD26<0,BD26,0) -> 0 | BF26: =IF(BD26-BE26<>0,BD26,0) -> 0
A27: 2326 | B27: RUIZ FABIANA ANDREA | C27: 264-4519628 | D27: RAWSON | E27: 11089 | F27: 59 | G27: 60000 | H27: -10000 | M27: 60000 | N27: =IF(H27>0,G27+H27-I27-J27-K27-L27-M27,G27-I27-J27-K27-L27-M27) -> 0 | O27: =G27+H27-J27-I27-K27-L27-M27 -> -10000 | P27: =IF(G27+H27<0,0,G27+H27) -> 50000 | Q27: 46245 | R27: 46244 | S27: 46213 | V27: MERCADO PAGO | X27: 7 | Y27: 7 | Z27: =IF(N27<0,0,N27) -> 0 | AH27: 1 | AI27: =IF(F27<=6,15,25) -> 25 | AJ27: =IF(O27<>0,25,15) -> 25 | AK27: =IF(AI27-T27=24,1,0) -> 0 | AL27: =IF(AH27-AK27=AH27,0,AH27) -> 0 | AM27: =IF(AK27<>0,U27,0) -> 0 | AN27: =IF(AK27=1,O27,0) -> 0 | AO27: =IF(AI27-T27=14,1,0) -> 0 | AP27: =IF(AH27-AO27=AH27,0,AH27) -> 0 | AQ27: =IF(AO27<>0,U27,0) -> 0 | AR27: =IF(AO27=1,O27,0) -> 0 | AS27: =IF(SUM(I27:M27)<>0,1,0) -> 1 | AT27: =AS27 -> 1 | AU27: =IF(O27>0,1,0) -> 0 | AV27: =IF(AK27+AO27+AU27=1,AU27,0) -> 0 | AW27: =IF(AI27-AV27=24,1,0) -> 0 | AX27: =IF(AH27-AW27=AH27,0,AH27) -> 0 | AY27: =IF(AW27=1,O27,0) -> 0 | AZ27: =IF(AY27-BA27<>0,AY27,0) -> 0 | BA27: =IF(AY27<0,AY27,0) -> 0 | BB27: =IF(AI27-AV27=14,1,0) -> 0 | BC27: =IF(AH27-BB27=AH27,0,AH27) -> 0 | BD27: =IF(BB27=1,O27,0) -> 0 | BE27: =IF(BD27<0,BD27,0) -> 0 | BF27: =IF(BD27-BE27<>0,BD27,0) -> 0
A28: 2339 | B28: ESCUDERO ANGELA VICTORIA | C28: 264-5534094 | D28: 9 DE JULIO | E28: 11193 | F28: 59 | G28: 60000 | H28: 0 | M28: 60000 | N28: =IF(H28>0,G28+H28-I28-J28-K28-L28-M28,G28-I28-J28-K28-L28-M28) -> 0 | O28: =G28+H28-J28-I28-K28-L28-M28 -> 0 | P28: =IF(G28+H28<0,0,G28+H28) -> 60000 | Q28: 46259 | R28: 46264 | S28: 46233 | V28: EFECTIVO OFICINA | X28: 7 | Y28: 7 | Z28: =IF(N28<0,0,N28) -> 0 | AH28: 1 | AI28: =IF(F28<=6,15,25) -> 25 | AJ28: =IF(O28<>0,25,15) -> 15 | AK28: =IF(AI28-T28=24,1,0) -> 0 | AL28: =IF(AH28-AK28=AH28,0,AH28) -> 0 | AM28: =IF(AK28<>0,U28,0) -> 0 | AN28: =IF(AK28=1,O28,0) -> 0 | AO28: =IF(AI28-T28=14,1,0) -> 0 | AP28: =IF(AH28-AO28=AH28,0,AH28) -> 0 | AQ28: =IF(AO28<>0,U28,0) -> 0 | AR28: =IF(AO28=1,O28,0) -> 0 | AS28: =IF(SUM(I28:M28)<>0,1,0) -> 1 | AT28: =AS28 -> 1 | AU28: =IF(O28>0,1,0) -> 0 | AV28: =IF(AK28+AO28+AU28=1,AU28,0) -> 0 | AW28: =IF(AI28-AV28=24,1,0) -> 0 | AX28: =IF(AH28-AW28=AH28,0,AH28) -> 0 | AY28: =IF(AW28=1,O28,0) -> 0 | AZ28: =IF(AY28-BA28<>0,AY28,0) -> 0 | BA28: =IF(AY28<0,AY28,0) -> 0 | BB28: =IF(AI28-AV28=14,1,0) -> 0 | BC28: =IF(AH28-BB28=AH28,0,AH28) -> 0 | BD28: =IF(BB28=1,O28,0) -> 0 | BE28: =IF(BD28<0,BD28,0) -> 0 | BF28: =IF(BD28-BE28<>0,BD28,0) -> 0
A29: 2360 | B29: NUÑEZ CHIRINO VIVIANA DEL CARMEN | C29: 264-6730916 | D29: POCITOS | E29: 11245 | F29: 59 | G29: 60000 | H29: 0 | M29: 60000 | N29: =IF(H29>0,G29+H29-I29-J29-K29-L29-M29,G29-I29-J29-K29-L29-M29) -> 0 | O29: =G29+H29-J29-I29-K29-L29-M29 -> 0 | P29: =IF(G29+H29<0,0,G29+H29) -> 60000 | Q29: 46237 | R29: 46237 | S29: 46216 | V29: MERCADO PAGO | X29: 7 | Y29: 7 | Z29: =IF(N29<0,0,N29) -> 0 | AH29: 1 | AI29: =IF(F29<=6,15,25) -> 25 | AJ29: =IF(O29<>0,25,15) -> 15 | AK29: =IF(AI29-T29=24,1,0) -> 0 | AL29: =IF(AH29-AK29=AH29,0,AH29) -> 0 | AM29: =IF(AK29<>0,U29,0) -> 0 | AN29: =IF(AK29=1,O29,0) -> 0 | AO29: =IF(AI29-T29=14,1,0) -> 0 | AP29: =IF(AH29-AO29=AH29,0,AH29) -> 0 | AQ29: =IF(AO29<>0,U29,0) -> 0 | AR29: =IF(AO29=1,O29,0) -> 0 | AS29: =IF(SUM(I29:M29)<>0,1,0) -> 1 | AT29: =AS29 -> 1 | AU29: =IF(O29>0,1,0) -> 0 | AV29: =IF(AK29+AO29+AU29=1,AU29,0) -> 0 | AW29: =IF(AI29-AV29=24,1,0) -> 0 | AX29: =IF(AH29-AW29=AH29,0,AH29) -> 0 | AY29: =IF(AW29=1,O29,0) -> 0 | AZ29: =IF(AY29-BA29<>0,AY29,0) -> 0 | BA29: =IF(AY29<0,AY29,0) -> 0 | BB29: =IF(AI29-AV29=14,1,0) -> 0 | BC29: =IF(AH29-BB29=AH29,0,AH29) -> 0 | BD29: =IF(BB29=1,O29,0) -> 0 | BE29: =IF(BD29<0,BD29,0) -> 0 | BF29: =IF(BD29-BE29<>0,BD29,0) -> 0
A30: 2374 | B30: ARABENA HECTOR ARIEL | C30: 264-4742020 | D30: SAN JUAN | E30: 11219 | F30: 58 | G30: 60000 | H30: -4500 | M30: 60000 | N30: =IF(H30>0,G30+H30-I30-J30-K30-L30-M30,G30-I30-J30-K30-L30-M30) -> 0 | O30: =G30+H30-J30-I30-K30-L30-M30 -> -4500 | P30: =IF(G30+H30<0,0,G30+H30) -> 55500 | Q30: 46265 | R30: 46265 | S30: 46234 | V30: MERCADO PAGO | X30: 7 | Y30: 7 | Z30: =IF(N30<0,0,N30) -> 0 | AH30: 1 | AI30: =IF(F30<=6,15,25) -> 25 | AJ30: =IF(O30<>0,25,15) -> 25 | AK30: =IF(AI30-T30=24,1,0) -> 0 | AL30: =IF(AH30-AK30=AH30,0,AH30) -> 0 | AM30: =IF(AK30<>0,U30,0) -> 0 | AN30: =IF(AK30=1,O30,0) -> 0 | AO30: =IF(AI30-T30=14,1,0) -> 0 | AP30: =IF(AH30-AO30=AH30,0,AH30) -> 0 | AQ30: =IF(AO30<>0,U30,0) -> 0 | AR30: =IF(AO30=1,O30,0) -> 0 | AS30: =IF(SUM(I30:M30)<>0,1,0) -> 1 | AT30: =AS30 -> 1 | AU30: =IF(O30>0,1,0) -> 0 | AV30: =IF(AK30+AO30+AU30=1,AU30,0) -> 0 | AW30: =IF(AI30-AV30=24,1,0) -> 0 | AX30: =IF(AH30-AW30=AH30,0,AH30) -> 0 | AY30: =IF(AW30=1,O30,0) -> 0 | AZ30: =IF(AY30-BA30<>0,AY30,0) -> 0 | BA30: =IF(AY30<0,AY30,0) -> 0 | BB30: =IF(AI30-AV30=14,1,0) -> 0 | BC30: =IF(AH30-BB30=AH30,0,AH30) -> 0 | BD30: =IF(BB30=1,O30,0) -> 0 | BE30: =IF(BD30<0,BD30,0) -> 0 | BF30: =IF(BD30-BE30<>0,BD30,0) -> 0
A31: 2461 | B31: ANDRES ESPINDOLA WALTER DARIO | C31: 264-4158966 | D31: POCITOS | E31: 11305 | F31: 57 | G31: 55000 | H31: 0 | M31: 55000 | N31: =IF(H31>0,G31+H31-I31-J31-K31-L31-M31,G31-I31-J31-K31-L31-M31) -> 0 | O31: =G31+H31-J31-I31-K31-L31-M31 -> 0 | P31: =IF(G31+H31<0,0,G31+H31) -> 55000 | Q31: 46248 | R31: 46248 | S31: 46217 | V31: MERCADO PAGO | X31: 7 | Y31: 7 | Z31: =IF(N31<0,0,N31) -> 0 | AH31: 1 | AI31: =IF(F31<=6,15,25) -> 25 | AJ31: =IF(O31<>0,25,15) -> 15 | AK31: =IF(AI31-T31=24,1,0) -> 0 | AL31: =IF(AH31-AK31=AH31,0,AH31) -> 0 | AM31: =IF(AK31<>0,U31,0) -> 0 | AN31: =IF(AK31=1,O31,0) -> 0 | AO31: =IF(AI31-T31=14,1,0) -> 0 | AP31: =IF(AH31-AO31=AH31,0,AH31) -> 0 | AQ31: =IF(AO31<>0,U31,0) -> 0 | AR31: =IF(AO31=1,O31,0) -> 0 | AS31: =IF(SUM(I31:M31)<>0,1,0) -> 1 | AT31: =AS31 -> 1 | AU31: =IF(O31>0,1,0) -> 0 | AV31: =IF(AK31+AO31+AU31=1,AU31,0) -> 0 | AW31: =IF(AI31-AV31=24,1,0) -> 0 | AX31: =IF(AH31-AW31=AH31,0,AH31) -> 0 | AY31: =IF(AW31=1,O31,0) -> 0 | AZ31: =IF(AY31-BA31<>0,AY31,0) -> 0 | BA31: =IF(AY31<0,AY31,0) -> 0 | BB31: =IF(AI31-AV31=14,1,0) -> 0 | BC31: =IF(AH31-BB31=AH31,0,AH31) -> 0 | BD31: =IF(BB31=1,O31,0) -> 0 | BE31: =IF(BD31<0,BD31,0) -> 0 | BF31: =IF(BD31-BE31<>0,BD31,0) -> 0
A32: 2486 | B32: ARIAS YESICA TAMARA | C32: 299-5486406 | D32: NEUQUEN | E32: 11347 | F32: 56 | G32: 40000 | H32: -45000 | M32: 40000 | N32: =IF(H32>0,G32+H32-I32-J32-K32-L32-M32,G32-I32-J32-K32-L32-M32) -> 0 | O32: =G32+H32-J32-I32-K32-L32-M32 -> -45000 | P32: =IF(G32+H32<0,0,G32+H32) -> 0 | Q32: 46246 | R32: 46246 | S32: 46216 | V32: MERCADO PAGO | X32: 7 | Y32: 7 | Z32: =IF(N32<0,0,N32) -> 0 | AH32: 1 | AI32: =IF(F32<=6,15,25) -> 25 | AJ32: =IF(O32<>0,25,15) -> 25 | AK32: =IF(AI32-T32=24,1,0) -> 0 | AL32: =IF(AH32-AK32=AH32,0,AH32) -> 0 | AM32: =IF(AK32<>0,U32,0) -> 0 | AN32: =IF(AK32=1,O32,0) -> 0 | AO32: =IF(AI32-T32=14,1,0) -> 0 | AP32: =IF(AH32-AO32=AH32,0,AH32) -> 0 | AQ32: =IF(AO32<>0,U32,0) -> 0 | AR32: =IF(AO32=1,O32,0) -> 0 | AS32: =IF(SUM(I32:M32)<>0,1,0) -> 1 | AT32: =AS32 -> 1 | AU32: =IF(O32>0,1,0) -> 0 | AV32: =IF(AK32+AO32+AU32=1,AU32,0) -> 0 | AW32: =IF(AI32-AV32=24,1,0) -> 0 | AX32: =IF(AH32-AW32=AH32,0,AH32) -> 0 | AY32: =IF(AW32=1,O32,0) -> 0 | AZ32: =IF(AY32-BA32<>0,AY32,0) -> 0 | BA32: =IF(AY32<0,AY32,0) -> 0 | BB32: =IF(AI32-AV32=14,1,0) -> 0 | BC32: =IF(AH32-BB32=AH32,0,AH32) -> 0 | BD32: =IF(BB32=1,O32,0) -> 0 | BE32: =IF(BD32<0,BD32,0) -> 0 | BF32: =IF(BD32-BE32<>0,BD32,0) -> 0
A33: 2489 | B33: YACANTE ALLENDE FRANCISCO JAVIER | C33: 264-4557852 | D33: SAN JUAN | E33: 11359 | F33: 56 | G33: 150000 | H33: -30000 | M33: 150000 | N33: =IF(H33>0,G33+H33-I33-J33-K33-L33-M33,G33-I33-J33-K33-L33-M33) -> 0 | O33: =G33+H33-J33-I33-K33-L33-M33 -> -30000 | P33: =IF(G33+H33<0,0,G33+H33) -> 120000 | Q33: 46261 | R33: 46261 | S33: 46227 | V33: EFECTIVO OFICINA | X33: 7 | Y33: 7 | Z33: =IF(N33<0,0,N33) -> 0 | AH33: 1 | AI33: =IF(F33<=6,15,25) -> 25 | AJ33: =IF(O33<>0,25,15) -> 25 | AK33: =IF(AI33-T33=24,1,0) -> 0 | AL33: =IF(AH33-AK33=AH33,0,AH33) -> 0 | AM33: =IF(AK33<>0,U33,0) -> 0 | AN33: =IF(AK33=1,O33,0) -> 0 | AO33: =IF(AI33-T33=14,1,0) -> 0 | AP33: =IF(AH33-AO33=AH33,0,AH33) -> 0 | AQ33: =IF(AO33<>0,U33,0) -> 0 | AR33: =IF(AO33=1,O33,0) -> 0 | AS33: =IF(SUM(I33:M33)<>0,1,0) -> 1 | AT33: =AS33 -> 1 | AU33: =IF(O33>0,1,0) -> 0 | AV33: =IF(AK33+AO33+AU33=1,AU33,0) -> 0 | AW33: =IF(AI33-AV33=24,1,0) -> 0 | AX33: =IF(AH33-AW33=AH33,0,AH33) -> 0 | AY33: =IF(AW33=1,O33,0) -> 0 | AZ33: =IF(AY33-BA33<>0,AY33,0) -> 0 | BA33: =IF(AY33<0,AY33,0) -> 0 | BB33: =IF(AI33-AV33=14,1,0) -> 0 | BC33: =IF(AH33-BB33=AH33,0,AH33) -> 0 | BD33: =IF(BB33=1,O33,0) -> 0 | BE33: =IF(BD33<0,BD33,0) -> 0 | BF33: =IF(BD33-BE33<>0,BD33,0) -> 0
A34: 2526 | B34: CRUZ INES CAROLINA | C34: 264-5111481 | D34: BARREAL | E34: 11399 | F34: 55 | G34: 50000 | H34: 0 | M34: 50000 | N34: =IF(H34>0,G34+H34-I34-J34-K34-L34-M34,G34-I34-J34-K34-L34-M34) -> 0 | O34: =G34+H34-J34-I34-K34-L34-M34 -> 0 | P34: =IF(G34+H34<0,0,G34+H34) -> 50000 | Q34: 46258 | R34: 46259 | S34: 46217 | V34: MERCADO PAGO | X34: 7 | Y34: 7 | Z34: =IF(N34<0,0,N34) -> 0 | AH34: 1 | AI34: =IF(F34<=6,15,25) -> 25 | AJ34: =IF(O34<>0,25,15) -> 15 | AK34: =IF(AI34-T34=24,1,0) -> 0 | AL34: =IF(AH34-AK34=AH34,0,AH34) -> 0 | AM34: =IF(AK34<>0,U34,0) -> 0 | AN34: =IF(AK34=1,O34,0) -> 0 | AO34: =IF(AI34-T34=14,1,0) -> 0 | AP34: =IF(AH34-AO34=AH34,0,AH34) -> 0 | AQ34: =IF(AO34<>0,U34,0) -> 0 | AR34: =IF(AO34=1,O34,0) -> 0 | AS34: =IF(SUM(I34:M34)<>0,1,0) -> 1 | AT34: =AS34 -> 1 | AU34: =IF(O34>0,1,0) -> 0 | AV34: =IF(AK34+AO34+AU34=1,AU34,0) -> 0 | AW34: =IF(AI34-AV34=24,1,0) -> 0 | AX34: =IF(AH34-AW34=AH34,0,AH34) -> 0 | AY34: =IF(AW34=1,O34,0) -> 0 | AZ34: =IF(AY34-BA34<>0,AY34,0) -> 0 | BA34: =IF(AY34<0,AY34,0) -> 0 | BB34: =IF(AI34-AV34=14,1,0) -> 0 | BC34: =IF(AH34-BB34=AH34,0,AH34) -> 0 | BD34: =IF(BB34=1,O34,0) -> 0 | BE34: =IF(BD34<0,BD34,0) -> 0 | BF34: =IF(BD34-BE34<>0,BD34,0) -> 0
A35: 2543 | B35: HIDALGO MORENO MAURO | C35: 264-4059779 | D35: SAN JUAN | E35: 11367 | F35: 54 | G35: 60000 | H35: 0 | M35: 60000 | N35: =IF(H35>0,G35+H35-I35-J35-K35-L35-M35,G35-I35-J35-K35-L35-M35) -> 0 | O35: =G35+H35-J35-I35-K35-L35-M35 -> 0 | P35: =IF(G35+H35<0,0,G35+H35) -> 60000 | Q35: 46265 | R35: 46265 | S35: 46234 | V35: MERCADO PAGO | X35: 7 | Y35: 7 | Z35: =IF(N35<0,0,N35) -> 0 | AH35: 1 | AI35: =IF(F35<=6,15,25) -> 25 | AJ35: =IF(O35<>0,25,15) -> 15 | AK35: =IF(AI35-T35=24,1,0) -> 0 | AL35: =IF(AH35-AK35=AH35,0,AH35) -> 0 | AM35: =IF(AK35<>0,U35,0) -> 0 | AN35: =IF(AK35=1,O35,0) -> 0 | AO35: =IF(AI35-T35=14,1,0) -> 0 | AP35: =IF(AH35-AO35=AH35,0,AH35) -> 0 | AQ35: =IF(AO35<>0,U35,0) -> 0 | AR35: =IF(AO35=1,O35,0) -> 0 | AS35: =IF(SUM(I35:M35)<>0,1,0) -> 1 | AT35: =AS35 -> 1 | AU35: =IF(O35>0,1,0) -> 0 | AV35: =IF(AK35+AO35+AU35=1,AU35,0) -> 0 | AW35: =IF(AI35-AV35=24,1,0) -> 0 | AX35: =IF(AH35-AW35=AH35,0,AH35) -> 0 | AY35: =IF(AW35=1,O35,0) -> 0 | AZ35: =IF(AY35-BA35<>0,AY35,0) -> 0 | BA35: =IF(AY35<0,AY35,0) -> 0 | BB35: =IF(AI35-AV35=14,1,0) -> 0 | BC35: =IF(AH35-BB35=AH35,0,AH35) -> 0 | BD35: =IF(BB35=1,O35,0) -> 0 | BE35: =IF(BD35<0,BD35,0) -> 0 | BF35: =IF(BD35-BE35<>0,BD35,0) -> 0
A36: 2545 | B36: DIAZ ANTONELLA YAMILA | C36: 264-4743505 | D36: JACHAL | E36: 11371 | F36: 54 | G36: 300000 | H36: 0 | N36: =IF(H36>0,G36+H36-I36-J36-K36-L36-M36,G36-I36-J36-K36-L36-M36) -> 300000 | O36: =G36+H36-J36-I36-K36-L36-M36 -> 300000 | P36: =IF(G36+H36<0,0,G36+H36) -> 300000 | R36: 46259 | S36: 46217 | W36: NO QUISO PAGAR EL JUEVES 3 VA POR OFICINA Y ALLI ARREGLA LO DE LAS CUOTAS | X36: 7 | Y36: 7 | Z36: =IF(N36<0,0,N36) -> 300000 | AH36: 1 | AI36: =IF(F36<=6,15,25) -> 25 | AJ36: =IF(O36<>0,25,15) -> 25 | AK36: =IF(AI36-T36=24,1,0) -> 0 | AL36: =IF(AH36-AK36=AH36,0,AH36) -> 0 | AM36: =IF(AK36<>0,U36,0) -> 0 | AN36: =IF(AK36=1,O36,0) -> 0 | AO36: =IF(AI36-T36=14,1,0) -> 0 | AP36: =IF(AH36-AO36=AH36,0,AH36) -> 0 | AQ36: =IF(AO36<>0,U36,0) -> 0 | AR36: =IF(AO36=1,O36,0) -> 0 | AS36: =IF(SUM(I36:M36)<>0,1,0) -> 0 | AT36: =AS36 -> 0 | AU36: =IF(O36>0,1,0) -> 1 | AV36: =IF(AK36+AO36+AU36=1,AU36,0) -> 1 | AW36: =IF(AI36-AV36=24,1,0) -> 1 | AX36: =IF(AH36-AW36=AH36,0,AH36) -> 1 | AY36: =IF(AW36=1,O36,0) -> 300000 | AZ36: =IF(AY36-BA36<>0,AY36,0) -> 300000 | BA36: =IF(AY36<0,AY36,0) -> 0 | BB36: =IF(AI36-AV36=14,1,0) -> 0 | BC36: =IF(AH36-BB36=AH36,0,AH36) -> 0 | BD36: =IF(BB36=1,O36,0) -> 0 | BE36: =IF(BD36<0,BD36,0) -> 0 | BF36: =IF(BD36-BE36<>0,BD36,0) -> 0
A37: 2548 | B37: LARA ELVIO ARNALDO | C37: 264-6613176 | D37: SAN JUAN | E37: 11381 | F37: 54 | G37: 60000 | H37: -10000 | M37: 60000 | N37: =IF(H37>0,G37+H37-I37-J37-K37-L37-M37,G37-I37-J37-K37-L37-M37) -> 0 | O37: =G37+H37-J37-I37-K37-L37-M37 -> -10000 | P37: =IF(G37+H37<0,0,G37+H37) -> 50000 | Q37: 46251 | R37: 46251 | S37: 46223 | V37: MERCADO PAGO | X37: 7 | Y37: 7 | Z37: =IF(N37<0,0,N37) -> 0 | AH37: 1 | AI37: =IF(F37<=6,15,25) -> 25 | AJ37: =IF(O37<>0,25,15) -> 25 | AK37: =IF(AI37-T37=24,1,0) -> 0 | AL37: =IF(AH37-AK37=AH37,0,AH37) -> 0 | AM37: =IF(AK37<>0,U37,0) -> 0 | AN37: =IF(AK37=1,O37,0) -> 0 | AO37: =IF(AI37-T37=14,1,0) -> 0 | AP37: =IF(AH37-AO37=AH37,0,AH37) -> 0 | AQ37: =IF(AO37<>0,U37,0) -> 0 | AR37: =IF(AO37=1,O37,0) -> 0 | AS37: =IF(SUM(I37:M37)<>0,1,0) -> 1 | AT37: =AS37 -> 1 | AU37: =IF(O37>0,1,0) -> 0 | AV37: =IF(AK37+AO37+AU37=1,AU37,0) -> 0 | AW37: =IF(AI37-AV37=24,1,0) -> 0 | AX37: =IF(AH37-AW37=AH37,0,AH37) -> 0 | AY37: =IF(AW37=1,O37,0) -> 0 | AZ37: =IF(AY37-BA37<>0,AY37,0) -> 0 | BA37: =IF(AY37<0,AY37,0) -> 0 | BB37: =IF(AI37-AV37=14,1,0) -> 0 | BC37: =IF(AH37-BB37=AH37,0,AH37) -> 0 | BD37: =IF(BB37=1,O37,0) -> 0 | BE37: =IF(BD37<0,BD37,0) -> 0 | BF37: =IF(BD37-BE37<>0,BD37,0) -> 0
A38: 2549 | B38: VAZQUEZ LUCIA NILDA | C38: 264-6194557 | D38: RAWSON | E38: 11382 | F38: 54 | G38: 60000 | H38: -24000 | M38: 60000 | N38: =IF(H38>0,G38+H38-I38-J38-K38-L38-M38,G38-I38-J38-K38-L38-M38) -> 0 | O38: =G38+H38-J38-I38-K38-L38-M38 -> -24000 | P38: =IF(G38+H38<0,0,G38+H38) -> 36000 | Q38: 46247 | R38: 46247 | S38: 46211 | V38: MERCADO PAGO | X38: 7 | Y38: 7 | Z38: =IF(N38<0,0,N38) -> 0 | AH38: 1 | AI38: =IF(F38<=6,15,25) -> 25 | AJ38: =IF(O38<>0,25,15) -> 25 | AK38: =IF(AI38-T38=24,1,0) -> 0 | AL38: =IF(AH38-AK38=AH38,0,AH38) -> 0 | AM38: =IF(AK38<>0,U38,0) -> 0 | AN38: =IF(AK38=1,O38,0) -> 0 | AO38: =IF(AI38-T38=14,1,0) -> 0 | AP38: =IF(AH38-AO38=AH38,0,AH38) -> 0 | AQ38: =IF(AO38<>0,U38,0) -> 0 | AR38: =IF(AO38=1,O38,0) -> 0 | AS38: =IF(SUM(I38:M38)<>0,1,0) -> 1 | AT38: =AS38 -> 1 | AU38: =IF(O38>0,1,0) -> 0 | AV38: =IF(AK38+AO38+AU38=1,AU38,0) -> 0 | AW38: =IF(AI38-AV38=24,1,0) -> 0 | AX38: =IF(AH38-AW38=AH38,0,AH38) -> 0 | AY38: =IF(AW38=1,O38,0) -> 0 | AZ38: =IF(AY38-BA38<>0,AY38,0) -> 0 | BA38: =IF(AY38<0,AY38,0) -> 0 | BB38: =IF(AI38-AV38=14,1,0) -> 0 | BC38: =IF(AH38-BB38=AH38,0,AH38) -> 0 | BD38: =IF(BB38=1,O38,0) -> 0 | BE38: =IF(BD38<0,BD38,0) -> 0 | BF38: =IF(BD38-BE38<>0,BD38,0) -> 0
A39: 2556 | B39: HORQUERA BARRRIONUEVO CLAUDIA ELIZABETH | C39: 264-4047122 | D39: POCITOS | E39: 11440 | F39: 54 | G39: 60000 | H39: 0 | M39: 60000 | N39: =IF(H39>0,G39+H39-I39-J39-K39-L39-M39,G39-I39-J39-K39-L39-M39) -> 0 | O39: =G39+H39-J39-I39-K39-L39-M39 -> 0 | P39: =IF(G39+H39<0,0,G39+H39) -> 60000 | Q39: 46254 | R39: 46254 | S39: 46223 | V39: MERCADO PAGO | X39: 7 | Y39: 7 | Z39: =IF(N39<0,0,N39) -> 0 | AH39: 1 | AI39: =IF(F39<=6,15,25) -> 25 | AJ39: =IF(O39<>0,25,15) -> 15 | AK39: =IF(AI39-T39=24,1,0) -> 0 | AL39: =IF(AH39-AK39=AH39,0,AH39) -> 0 | AM39: =IF(AK39<>0,U39,0) -> 0 | AN39: =IF(AK39=1,O39,0) -> 0 | AO39: =IF(AI39-T39=14,1,0) -> 0 | AP39: =IF(AH39-AO39=AH39,0,AH39) -> 0 | AQ39: =IF(AO39<>0,U39,0) -> 0 | AR39: =IF(AO39=1,O39,0) -> 0 | AS39: =IF(SUM(I39:M39)<>0,1,0) -> 1 | AT39: =AS39 -> 1 | AU39: =IF(O39>0,1,0) -> 0 | AV39: =IF(AK39+AO39+AU39=1,AU39,0) -> 0 | AW39: =IF(AI39-AV39=24,1,0) -> 0 | AX39: =IF(AH39-AW39=AH39,0,AH39) -> 0 | AY39: =IF(AW39=1,O39,0) -> 0 | AZ39: =IF(AY39-BA39<>0,AY39,0) -> 0 | BA39: =IF(AY39<0,AY39,0) -> 0 | BB39: =IF(AI39-AV39=14,1,0) -> 0 | BC39: =IF(AH39-BB39=AH39,0,AH39) -> 0 | BD39: =IF(BB39=1,O39,0) -> 0 | BE39: =IF(BD39<0,BD39,0) -> 0 | BF39: =IF(BD39-BE39<>0,BD39,0) -> 0
A40: 2578 | B40: LEPEZ MEDINA MIRIAM AYELEN | C40: 264-5143197 | D40: SAN JUAN | E40: 11425 | F40: 53 | G40: 60000 | H40: 0 | M40: 60000 | N40: =IF(H40>0,G40+H40-I40-J40-K40-L40-M40,G40-I40-J40-K40-L40-M40) -> 0 | O40: =G40+H40-J40-I40-K40-L40-M40 -> 0 | P40: =IF(G40+H40<0,0,G40+H40) -> 60000 | Q40: 46265 | R40: 46265 | S40: 46234 | V40: MERCADO PAGO | X40: 7 | Y40: 7 | Z40: =IF(N40<0,0,N40) -> 0 | AH40: 1 | AI40: =IF(F40<=6,15,25) -> 25 | AJ40: =IF(O40<>0,25,15) -> 15 | AK40: =IF(AI40-T40=24,1,0) -> 0 | AL40: =IF(AH40-AK40=AH40,0,AH40) -> 0 | AM40: =IF(AK40<>0,U40,0) -> 0 | AN40: =IF(AK40=1,O40,0) -> 0 | AO40: =IF(AI40-T40=14,1,0) -> 0 | AP40: =IF(AH40-AO40=AH40,0,AH40) -> 0 | AQ40: =IF(AO40<>0,U40,0) -> 0 | AR40: =IF(AO40=1,O40,0) -> 0 | AS40: =IF(SUM(I40:M40)<>0,1,0) -> 1 | AT40: =AS40 -> 1 | AU40: =IF(O40>0,1,0) -> 0 | AV40: =IF(AK40+AO40+AU40=1,AU40,0) -> 0 | AW40: =IF(AI40-AV40=24,1,0) -> 0 | AX40: =IF(AH40-AW40=AH40,0,AH40) -> 0 | AY40: =IF(AW40=1,O40,0) -> 0 | AZ40: =IF(AY40-BA40<>0,AY40,0) -> 0 | BA40: =IF(AY40<0,AY40,0) -> 0 | BB40: =IF(AI40-AV40=14,1,0) -> 0 | BC40: =IF(AH40-BB40=AH40,0,AH40) -> 0 | BD40: =IF(BB40=1,O40,0) -> 0 | BE40: =IF(BD40<0,BD40,0) -> 0 | BF40: =IF(BD40-BE40<>0,BD40,0) -> 0
...

Sheet PENDIENTES AGOSTO
A1: 7 | B1: =IF(A1<>0,VLOOKUP(A1,COB!A1:B9,2),"COBRADOR INEXISTENTE") -> MEDIOS ELECTRONICOS | D1: AGOSTO | E1: 2026 | F1: TOTAL | I1: EL ARRASTE ES EL DINERO PENDIENTE O A FAVOR DEL CLIENTE
G2: A COBRAR | I2: PAGOS | N2: SAL. REAL | O2: SALDO | P2: SALDO /P ESTAD | Q2: FECHAS
A3: COD | B3: CLIENTE | C3: TELEFONO | D3: LOCALIDAD | E3: SOLI | F3: CTA | G3: CUOTAS | H3: ARRASTRE | I3: PAGO | J3: PAGO X ADEL | K3: PAGO ANTES | L3: X OFICINA | M3: BCO O ELECT | N3: CON MORA | O3: SISTEMA | P3: PLANILLA SALIDA | Q3: PAGO | R3: PAGARA | S3: PAGO MES ANT | T3: BAJA | U3: MOTIVO | V3: OBSERVACIONES | W3: TERMOMETRO
A4: 2015 | B4: ELIZONDO MARIO SANTIAGO | C4: 264-5061888 | D4: ALBARDON | E4: 10189 | F4: 66 | G4: 70000 | H4: -118000 | N4: =IF(H4>0,G4+H4-I4-J4-K4-L4-M4,G4-I4-J4-K4-L4-M4) -> 70000 | O4: =G4+H4-J4-I4-K4-L4-M4 -> -48000 | P4: =IF(G4+H4<0,0,G4+H4) -> 0 | S4: 70000 | T4: 1 | U4: 1 | V4: BAJA Y DEVOLUCION
A5: 2545 | B5: DIAZ ANTONELLA YAMILA | C5: 264-4743505 | D5: JACHAL | E5: 11371 | F5: 54 | G5: 300000 | H5: 0 | N5: =IF(H5>0,G5+H5-I5-J5-K5-L5-M5,G5-I5-J5-K5-L5-M5) -> 300000 | O5: =G5+H5-J5-I5-K5-L5-M5 -> 300000 | P5: =IF(G5+H5<0,0,G5+H5) -> 300000 | R5: 46259 | S5: 46217 | W5: NO QUISO PAGAR EL JUEVES 3 VA POR OFICINA Y ALLI ARREGLA LO DE LAS CUOTAS
A6: 2897 | B6: ESPEJO ALEXANDRA VANESA | C6: 264-5163415 | D6: SAN JUAN | E6: 11810 | F6: 41 | G6: 80000 | H6: 0 | N6: =IF(H6>0,G6+H6-I6-J6-K6-L6-M6,G6-I6-J6-K6-L6-M6) -> 80000 | O6: =G6+H6-J6-I6-K6-L6-M6 -> 80000 | P6: =IF(G6+H6<0,0,G6+H6) -> 80000 | R6: 46264 | S6: 46218 | W6: NO PAGO PROBLEMAS ECONOMICOS
A7: 3036 | B7: FALCON ARTEZ YANINA VANESA | C7: 264-4806498 | D7: CHIMBAS | E7: 10489 | F7: 36 | G7: 100000 | H7: 0 | N7: =IF(H7>0,G7+H7-I7-J7-K7-L7-M7,G7-I7-J7-K7-L7-M7) -> 100000 | O7: =G7+H7-J7-I7-K7-L7-M7 -> 100000 | P7: =IF(G7+H7<0,0,G7+H7) -> 100000 | R7: 46265 | S7: 46234 | W7: VA PAGAR EL DIA JUEVES 3 PORQUE NO TENIA PAGA LAS DOS JUNTAS
A8: 3118 | B8: MACIAS DANIELA VALERIA | C8: 264-4038388 | D8: SAN JUAN | E8: 11940 | F8: 35 | G8: 60000 | H8: 60000 | N8: =IF(H8>0,G8+H8-I8-J8-K8-L8-M8,G8-I8-J8-K8-L8-M8) -> 120000 | O8: =G8+H8-J8-I8-K8-L8-M8 -> 120000 | P8: =IF(G8+H8<0,0,G8+H8) -> 120000 | R8: 46233 | S8: 46203 | T8: 1 | U8: 1 | V8: BAJA POR FALTADE PAGO Y COMUNICACIÓN
A9: 3158 | B9: POBLETE VIVIANA GRACIELA | C9: 264-4630593 | D9: RODEO | E9: 20018 | F9: 34 | G9: 80000 | H9: 0 | N9: =IF(H9>0,G9+H9-I9-J9-K9-L9-M9,G9-I9-J9-K9-L9-M9) -> 80000 | O9: =G9+H9-J9-I9-K9-L9-M9 -> 80000 | P9: =IF(G9+H9<0,0,G9+H9) -> 80000 | R9: 46259 | S9: 46209 | W9: NO RESPONDE PERO NO DARE DE BAJA
A10: 3177 | B10: ALCARAZ RICARDO RAMON | C10: 264-5794260 | D10: EL RINCON | E10: 11939 | F10: 34 | G10: 30000 | H10: 15000 | N10: =IF(H10>0,G10+H10-I10-J10-K10-L10-M10,G10-I10-J10-K10-L10-M10) -> 45000 | O10: =G10+H10-J10-I10-K10-L10-M10 -> 45000 | P10: =IF(G10+H10<0,0,G10+H10) -> 45000 | R10: 46264 | S10: 46203 | W10: PAGA LAS DOS JUNTAS EL 3/08
A11: 3249 | B11: SAIRE NATALIA LORENA | C11: 264-5069280 | D11: CHIMBAS | E11: 20300 | F11: 32 | G11: 60000 | H11: 60000 | M11: 60000 | N11: =IF(H11>0,G11+H11-I11-J11-K11-L11-M11,G11-I11-J11-K11-L11-M11) -> 60000 | O11: =G11+H11-J11-I11-K11-L11-M11 -> 60000 | P11: =IF(G11+H11<0,0,G11+H11) -> 120000 | Q11: 46245 | R11: 46245 | S11: 46211 | V11: MERCADO PAGO | W11: PAGO JULIO DEBE AGOSTO
A12: 3371 | B12: PAEZ ILIANA YAEL | C12: 264-6299108 | D12: SAN JUAN | E12: 20186 | F12: 27 | G12: 99999 | H12: -13 | N12: =IF(H12>0,G12+H12-I12-J12-K12-L12-M12,G12-I12-J12-K12-L12-M12) -> 99999 | O12: =G12+H12-J12-I12-K12-L12-M12 -> 99986 | P12: =IF(G12+H12<0,0,G12+H12) -> 99986 | R12: 46261 | S12: 46230 | W12: PAGA EN SEPTIEMBRE LAS DOS JUNTAS
A13: 3400 | B13: CALIVA PAMELA LORENA | C13: 264-5899505 | D13: POCITOS | E13: 20201 | F13: 25 | G13: 60000 | H13: 0 | N13: =IF(H13>0,G13+H13-I13-J13-K13-L13-M13,G13-I13-J13-K13-L13-M13) -> 60000 | O13: =G13+H13-J13-I13-K13-L13-M13 -> 60000 | P13: =IF(G13+H13<0,0,G13+H13) -> 60000 | S13: 46211 | W13: NO RESPONDE PERO NO DARE DE BAJA
A14: 3401 | B14: NIEVAS CINTHYA DAYANA | C14: 264-6216892 | D14: RAWSON | E14: 20219 | F14: 25 | G14: 60000 | H14: -60000 | N14: =IF(H14>0,G14+H14-I14-J14-K14-L14-M14,G14-I14-J14-K14-L14-M14) -> 60000 | O14: =G14+H14-J14-I14-K14-L14-M14 -> 0 | P14: =IF(G14+H14<0,0,G14+H14) -> 0 | R14: 46234 | S14: 46234 | W14: ELLA YA PAGO EN JULIO ESTA CUOTA
A15: 3457 | B15: JIMENEZ HERNAN | C15: 264-5430399 | D15: CHIMBAS | E15: 20336 | F15: 22 | G15: 80000 | H15: 0 | N15: =IF(H15>0,G15+H15-I15-J15-K15-L15-M15,G15-I15-J15-K15-L15-M15) -> 80000 | O15: =G15+H15-J15-I15-K15-L15-M15 -> 80000 | P15: =IF(G15+H15<0,0,G15+H15) -> 80000 | R15: 46234 | S15: 46234 | W15: RECLAMO POR PROPUESTA
A16: 3491 | B16: SIMAN JUANA BEATRIZ | C16: 264-5058882 | D16: SAN JUAN | E16: 20356 | F16: 15 | G16: 200000 | H16: 0 | N16: =IF(H16>0,G16+H16-I16-J16-K16-L16-M16,G16-I16-J16-K16-L16-M16) -> 200000 | O16: =G16+H16-J16-I16-K16-L16-M16 -> 200000 | P16: =IF(G16+H16<0,0,G16+H16) -> 200000 | S16: 46206 | T16: 1 | U16: 1 | V16: BAJA INFORMA EDUARDO
B17: TOTAL COB SIN CUP | G17: ='COBRANZA SIN CUPONES'!G26 -> 0 | I17: ='COBRANZA SIN CUPONES'!H26 -> 525000 | J17: ='COBRANZA SIN CUPONES'!I26 -> 0 | O17: =G17+H17-J17-I17-K17-L17-M17 -> -525000
P26: OBLIGACION DE PAGO
A27: =COUNTIF(X4:X16,A1) -> 0 | B27: CLIENTES | C27: TOTAL COBRANZA NORMAL ----> | E27: =I27 -> 0 | F27: A COBRAR | G27: =SUMIF(X4:X16,A1,G4:G16) -> 0 | H27: =SUMIF(X4:X16,A1,H4:H16) -> 0 | I27: =SUMIF(X4:X16,A1,I4:I16) -> 0 | J27: =SUMIF(X4:X16,A1,J4:J16) -> 0 | K27: =SUMIF(X4:X16,A1,K4:K16) -> 0 | L27: =SUMIF(X4:X16,A1,L4:L16) -> 0 | M27: =SUMIF(X4:X16,A1,M4:M16) -> 0 | N27: =SUM(N4:N17) -> 1354999 | O27: =SUMIF(X4:X16,A1,O4:O16) -> 0 | P27: =SUMIF(X4:X16,A1,P4:P16) -> 0 | Q27: =P27-O27 -> 0 | T27: =SUMIF(X4:X16,A1,T4:T16) -> 0 | U27: =COUNTIFS(X1:X16,A1,U1:U16,"<=5") -> 0

Sheet COBRANZA SIN CUPONES
A1: COBRANZA SIN CUPONES
H2: PAGOS
H3: AUTOHOGAR
A4: COD | B4: CLIENTE | C4: TELEFONO | D4: LOCALIDAD | E4: SOLI | F4: N°CUOTA | G4: VALOR CUOTA | H4: PAGO | I4: PAGO X ADEL | J4: TOTAL | K4: COMISION | L4: A RENDIR | M4: N° COBRADOR | N4: OBSERVACIONES
A5: 1449 | B5: ESCUELA ANA LORENA | E5: 8865 | H5: 160000 | J5: =H5+I5 -> 160000 | K5: =J5*AUTOHOGAR!$M$165% -> 12800 | L5: =J5-K5 -> 147200
A6: 2947 | B6: CASTRO FLORES | E6: 11832 | H6: 40000 | J6: =H6+I6 -> 40000 | K6: =J6*AUTOHOGAR!$M$165% -> 3200 | L6: =J6-K6 -> 36800
A7: 3145 | B7: MONTAÑA MARGARITA | E7: 11961 | H7: 60000 | J7: =H7+I7 -> 60000 | K7: =J7*AUTOHOGAR!$M$165% -> 4800 | L7: =J7-K7 -> 55200
A8: 3056 | B8: GONZALEZ MARCELA | E8: 10167 | G8: 60000 | H8: 115000 | J8: =H8+I8 -> 115000 | K8: =J8*AUTOHOGAR!$M$165% -> 9200 | L8: =J8-K8 -> 105800
A9: 3444 | B9: GOMEZ LILIANA | E9: 20302 | H9: 150000 | J9: =H9+I9 -> 150000 | K9: =J9*AUTOHOGAR!$M$165% -> 12000 | L9: =J9-K9 -> 138000
J10: =H10+I10 -> 0 | K10: =J10*AUTOHOGAR!$M$165% -> 0 | L10: =J10-K10 -> 0
J11: =H11+I11 -> 0 | K11: =J11*AUTOHOGAR!$M$165% -> 0 | L11: =J11-K11 -> 0
J12: =H12+I12 -> 0 | K12: =J12*AUTOHOGAR!$M$165% -> 0 | L12: =J12-K12 -> 0
J13: =H13+I13 -> 0 | K13: =J13*AUTOHOGAR!$M$165% -> 0 | L13: =J13-K13 -> 0
J14: =H14+I14 -> 0 | K14: =J14*AUTOHOGAR!$M$165% -> 0 | L14: =J14-K14 -> 0
J15: =H15+I15 -> 0 | K15: =J15*AUTOHOGAR!$M$165% -> 0 | L15: =J15-K15 -> 0
J16: =H16+I16 -> 0 | K16: =J16*AUTOHOGAR!$M$165% -> 0 | L16: =J16-K16 -> 0
J17: =H17+I17 -> 0 | K17: =J17*AUTOHOGAR!$M$165% -> 0 | L17: =J17-K17 -> 0
J18: =H18+I18 -> 0 | K18: =J18*AUTOHOGAR!$M$165% -> 0 | L18: =J18-K18 -> 0
J19: =H19+I19 -> 0 | K19: =J19*AUTOHOGAR!$M$165% -> 0 | L19: =J19-K19 -> 0
J20: =H20+I20 -> 0 | K20: =J20*AUTOHOGAR!$M$165% -> 0 | L20: =J20-K20 -> 0
J21: =H21+I21 -> 0 | K21: =J21*AUTOHOGAR!$M$165% -> 0 | L21: =J21-K21 -> 0
... J24: =H24+I24 -> 0 | K24: =J24*AUTOHOGAR!$M$165% -> 0 | L24: =J24-K24 -> 0
A26: =COUNTA(A5:A24) -> 5 | H26: =SUM(H5:H25) -> 525000 | I26: =SUM(I5:I25) -> 0 | J26: =SUM(J5:J25) -> 525000 | K26: =SUM(K5:K25) -> 42000 | L26: =SUM(L5:L25) -> 483000

Sheet PAGARA
A1: CLIENTE | B1: (Todas)
A3: Etiquetas de fila | B3: Suma de CON MORA
A4: (en blanco) | B4: 476000
A5: Total general | B5: 476000

Sheet PAGARA DETALLADO
A3: Suma de CON MORA | B3: Etiquetas de columna
A4: Etiquetas de fila | B4: (en blanco) | C4: Total general
A5: ESTRELLA MICAELA DEL ROCIO | B5: 11000 | C5: 11000 | R5: 45540
A6: RAMIREZ PAULA ALEJANDRA | B6: 15000 | C6: 15000
A7: MOLINI BETINA LAURA | B7: 10000 | C7: 10000
A8: AGUILAR FIDEL CHOQUE | B8: 20000 | C8: 20000
A9: OYOLA SANCHEZ SABRINA MAILEN | B9: 4000 | C9: 4000 | M9: 30000 | Q9: 45547 | V9: GALICIA
A10: CARRIZO ALEJANDRA NELLY | B10: 9000 | C10: 9000 | R10: 45551
A11: HERRERA FRANCISCO ANTONIO | B11: 12000 | C11: 12000
A12: CARPIO NORMA ANA | B12: 7000 | C12: 7000
A13: LORENZETTI LANZILOTTA SANDRA P. | B13: 10000 | C13: 10000
A14: VARGAS MARIA HORTENCIA | B14: 6000 | C14: 6000 | R14: 45625
A15: BALMACEDA MAZA FRANCISCO EMILIO | B15: 7000 | C15: 7000 | R15: 45618
A16: CAJAS HUGO RICARDO | B16: 10000 | C16: 10000 | V16: en febro aumenta esta con un prestamo
A17: OCHOA BARBARA YAMILA | B17: 6000 | C17: 6000 | I17: 30000 | Q17: 45542
A18: ALANIZ CINTIA MACARENA | B18: 5000 | C18: 5000
A19: HEREDIA JUAN CARLOS | B19: 10000 | C19: 10000
A20: AGÜERO PATRICIO JAVIER | B20: 5000 | C20: 5000 | I20: 30000 | Q20: 45545
A21: BUSTOS NELLY MABEL | B21: 6800 | C21: 6800 | I21: 30000 | Q21: 45547 | V21: aumenta a 60.000
A22: ZAMBRA MARIA SOLEDAD | B22: 10000 | C22: 10000 | M22: 30000 | Q22: 45547 | R22: 45547
A23: GALDEANO CARRIZO HERNAN | B23: 8000 | C23: 8000
A24: PASTEN OLMOS ROSA MANUELA | B24: 4500 | C24: 4500
A25: AGUERO CARLOS MORENO | B25: 9000 | C25: 9000
A26: PUJADO LOBOS MARTIN DAVID | B26: 3000 | C26: 3000
A27: MARINERO GERMAN ANTONIO | B27: 10000 | C27: 10000
A28: MOLINA EMANUEL MARCOS JAIRO | B28: 8000 | C28: 8000 | R28: 45551 | V28: no aumenta
A29: OCAMPO BLAS RICARDO | B29: 7000 | C29: 7000
A30: MERCADO ANA BELEN | B30: 7000 | C30: 7000
A31: KENNY NOELIA VANESA | B31: 10000 | C31: 10000
A32: CAROSELLI YANINA CAROLINA | B32: 6000 | C32: 6000 | I32: 30000 | Q32: 45615 | R32: 45615 | V32: no aumenta
A33: PEREZ LUCAS SEBASTIAN | B33: 4000 | C33: 4000
A34: SALCEDO JORGE LUIS | B34: 8500 | C34: 8500
A35: NUÑEZ PAMELA GISELLE | B35: 8000 | C35: 8000
A36: GUTIERREZ ATENCIO ELDA VANESA | B36: 10000 | C36: 10000 | R36: 45551
A37: CEVALLE JORGE LEONARDO | B37: 12000 | C37: 12000 | I37: 35000 | Q37: 45615 | R37: 45615 | V37: aumenta a 55.000
A38: SILLERO GABRIELA SOLEDAD | B38: 5000 | C38: 5000
A39: NAVARRO EDUARDO AGUSTIN | B39: 15000 | C39: 15000 | V39: no aumenta
A40: RIVEROS DAYANA ESTEFANIA | B40: 10000 | C40: 10000 | R40: 45623
A41: CASTRO OSCAR ALBERTO | B41: 9700 | C41: 9700 | R41: 45617
A42: ARIA MIRTA GLADYS | B42: 5000 | C42: 5000
...

Sheet COB
A1: 1 | B1: BANCO | C1: 1
A2: 2 | B2: OFICINA SAN JUAN | C2: 3
A3: 3 | C3: 1
A4: 4 | B4: COBRADOR SAN JUAN | C4: 2
A5: 5 | C5: 1
A6: 6 | C6: 1
A7: 7 | B7: MEDIOS ELECTRONICOS | C7: 3
A8: 8 | C8: 2
A9: 9 | C9: 2
B14: BANCO O M ELECTRONICOS | C14: =COUNTIF(C1:C9,1) -> 4
B15: COBRADORES | C15: =COUNTIF(C1:C9,2) -> 3
B16: SUCURSALES | C16: =COUNTIF(C1:C9,3) -> 2
B17: OTRO MEDIO | C17: =COUNTIF(C1:C9,4) -> 0
C19: =SUM(C14:C18) -> 9
